Workbook

Sheet 学生诊断报告
A1: 剑桥英语级别诊断报告 (V22 终极兼容版)
H2: 日期 | I2: 成绩
A3: 请选择学生姓名: | B3: 王海晴 Cherry Wang | H3: 15/09/2025 | I3: 136
H4: 46126 | I4: =IF($B$3="","", IFERROR(INDEX(Helper_AllData!V:V, _xludf.AGGREGATE(15,6,ROW(Helper_AllData!$A$2:$A$1000)/(Helper_AllData!$A$2:$A$1000=$B$3),2)),""))
A5: 报考级别 (Level): | B5: =IF($B$3="","", IFERROR(LOOKUP(2, 1/(Helper_AllData!$A$2:$A$1000=$B$3), Helper_AllData!$D$2:$D$1000), "")) -> Movers | H5: =IF($B$3="","", IFERROR(INDEX(Helper_AllData!B:B, _xludf.AGGREGATE(15,6,ROW(Helper_AllData!$A$2:$A$1000)/(Helper_AllData!$A$2:$A$1000=$B$3),3)),"")) | I5: =IF($B$3="","", IFERROR(INDEX(Helper_AllData!V:V, _xludf.AGGREGATE(15,6,ROW(Helper_AllData!$A$2:$A$1000)/(Helper_AllData!$A$2:$A$1000=$B$3),3)),""))
A6: 总分 / 盾牌 (Total): | B6: =IF($B$3="","", IFERROR(LOOKUP(2, 1/(Helper_AllData!$A$2:$A$1000=$B$3), Helper_AllData!$V$2:$V$1000), "")) -> 3 | H6: =IF($B$3="","", IFERROR(INDEX(Helper_AllData!B:B, _xludf.AGGREGATE(15,6,ROW(Helper_AllData!$A$2:$A$1000)/(Helper_AllData!$A$2:$A$1000=$B$3),4)),"")) | I6: =IF($B$3="","", IFERROR(INDEX(Helper_AllData!V:V, _xludf.AGGREGATE(15,6,ROW(Helper_AllData!$A$2:$A$1000)/(Helper_AllData!$A$2:$A$1000=$B$3),4)),""))
H7: =IF($B$3="","", IFERROR(INDEX(Helper_AllData!B:B, _xludf.AGGREGATE(15,6,ROW(Helper_AllData!$A$2:$A$1000)/(Helper_AllData!$A$2:$A$1000=$B$3),5)),"")) | I7: =IF($B$3="","", IFERROR(INDEX(Helper_AllData!V:V, _xludf.AGGREGATE(15,6,ROW(Helper_AllData!$A$2:$A$1000)/(Helper_AllData!$A$2:$A$1000=$B$3),5)),""))
A8: =IF($B$3="","", IF(OR(B5="Flyers", B5="Movers"), "R&W 盾牌 (Shields):", "Reading Scale:")) -> R&W 盾牌 (Shields): | B8: =IF($B$3="","", IFERROR(LOOKUP(2, 1/(Helper_AllData!$A$2:$A$1000=$B$3), Helper_AllData!$L$2:$L$1000), "")) -> 1 | H8: =IF($B$3="","", IFERROR(INDEX(Helper_AllData!B:B, _xludf.AGGREGATE(15,6,ROW(Helper_AllData!$A$2:$A$1000)/(Helper_AllData!$A$2:$A$1000=$B$3),6)),"")) | I8: =IF($B$3="","", IFERROR(INDEX(Helper_AllData!V:V, _xludf.AGGREGATE(15,6,ROW(Helper_AllData!$A$2:$A$1000)/(Helper_AllData!$A$2:$A$1000=$B$3),6)),""))
A9: =IF($B$3="","", IF(OR(B5="Flyers", B5="Movers"), "-", "Writing Scale:")) -> - | B9: =IF($B$3="","", IF(OR(B5="Flyers", B5="Movers"), "-", LOOKUP(2, 1/(Helper_AllData!$A$2:$A$1000=$B$3), Helper_AllData!$O$2:$O$1000))) -> - | H9: =IF($B$3="","", IFERROR(INDEX(Helper_AllData!B:B, _xludf.AGGREGATE(15,6,ROW(Helper_AllData!$A$2:$A$1000)/(Helper_AllData!$A$2:$A$1000=$B$3),7)),"")) | I9: =IF($B$3="","", IFERROR(INDEX(Helper_AllData!V:V, _xludf.AGGREGATE(15,6,ROW(Helper_AllData!$A$2:$A$1000)/(Helper_AllData!$A$2:$A$1000=$B$3),7)),""))
A10: =IF($B$3="","", IF(OR(B5="Flyers", B5="Movers"), "Listening 盾牌 (Shields):", "Listening Scale:")) -> Listening 盾牌 (Shields): | B10: =IF($B$3="","", IFERROR(LOOKUP(2, 1/(Helper_AllData!$A$2:$A$1000=$B$3), Helper_AllData!$U$2:$U$1000), "")) -> 2 | H10: =IF($B$3="","", IFERROR(INDEX(Helper_AllData!B:B, _xludf.AGGREGATE(15,6,ROW(Helper_AllData!$A$2:$A$1000)/(Helper_AllData!$A$2:$A$1000=$B$3),8)),"")) | I10: =IF($B$3="","", IFERROR(INDEX(Helper_AllData!V:V, _xludf.AGGREGATE(15,6,ROW(Helper_AllData!$A$2:$A$1000)/(Helper_AllData!$A$2:$A$1000=$B$3),8)),""))
H11: =IF($B$3="","", IFERROR(INDEX(Helper_AllData!B:B, _xludf.AGGREGATE(15,6,ROW(Helper_AllData!$A$2:$A$1000)/(Helper_AllData!$A$2:$A$1000=$B$3),9)),"")) | I11: =IF($B$3="","", IFERROR(INDEX(Helper_AllData!V:V, _xludf.AGGREGATE(15,6,ROW(Helper_AllData!$A$2:$A$1000)/(Helper_AllData!$A$2:$A$1000=$B$3),9)),""))
A12: 【核心能力诊断与建议】 | H12: =IF($B$3="","", IFERROR(INDEX(Helper_AllData!B:B, _xludf.AGGREGATE(15,6,ROW(Helper_AllData!$A$2:$A$1000)/(Helper_AllData!$A$2:$A$1000=$B$3),10)),"")) | I12: =IF($B$3="","", IFERROR(INDEX(Helper_AllData!V:V, _xludf.AGGREGATE(15,6,ROW(Helper_AllData!$A$2:$A$1000)/(Helper_AllData!$A$2:$A$1000=$B$3),10)),""))
A13: 阅读/读写建议: | B13: =IF($B$3="","", IFERROR(LOOKUP(2, 1/(Helper_AllData!$A$2:$A$1000=$B$3), Helper_AllData!$X$2:$X$1000), "")) -> ⚠️ 薄弱环节: RW-Pt5 📉 考察能力: [读写] 阅读故事补全句子 💡 提升建议: 练习同义替换，答案通常直接来自文章，不要自己编造。
A14: 写作建议: | B14: =IF($B$3="","", IFERROR(LOOKUP(2, 1/(Helper_AllData!$A$2:$A$1000=$B$3), Helper_AllData!$Y$2:$Y$1000), "")) -> 0
A15: 听力建议: | B15: =IF($B$3="","", IFERROR(LOOKUP(2, 1/(Helper_AllData!$A$2:$A$1000=$B$3), Helper_AllData!$Z$2:$Z$1000), "")) -> ⚠️ 薄弱环节: L-Pt3 📉 考察能力: [听力] 图片匹配 (星期/活动) 💡 提升建议: 听完整的句子，注意区分过去几天做了什么，留意干扰项。

Sheet 班级板块精细诊断
A1: 班级分项能力看板
A3: 1. 选择SET: | B3: B1
A4: 2. 选择级别: | B4: Flyers
A5: 3. 选择科目: | B5: Listening
A8: Part 1 | B8: =IF(OR(AND($B$5="Writing", 1>2), AND($B$5="Listening", 1>5)), "-", IFERROR(AVERAGEIFS(OFFSET(Helper_AllData!$A:$A, 0, IF($B$5="Reading", 3+1, IF($B$5="Writing", 11+1, 14+1))), Helper_AllData!$C:$C, $B$3, Helper_AllData!$D:$D, $B$4), 0)) -> 0 | C8: =IF(B8="-", "-", IF(B8=0, "-", IF(B8<MAX($B$8:$B$14)*0.8, "🚨 重点突击", "✅ 稳健"))) -> -
A9: Part 2 | B9: =IF(OR(AND($B$5="Writing", 2>2), AND($B$5="Listening", 2>5)), "-", IFERROR(AVERAGEIFS(OFFSET(Helper_AllData!$A:$A, 0, IF($B$5="Reading", 3+2, IF($B$5="Writing", 11+2, 14+2))), Helper_AllData!$C:$C, $B$3, Helper_AllData!$D:$D, $B$4), 0)) -> 4.72 | C9: =IF(B9="-", "-", IF(B9=0, "-", IF(B9<MAX($B$8:$B$14)*0.8, "🚨 重点突击", "✅ 稳健"))) -> ✅ 稳健
A10: Part 3 | B10: =IF(OR(AND($B$5="Writing", 3>2), AND($B$5="Listening", 3>5)), "-", IFERROR(AVERAGEIFS(OFFSET(Helper_AllData!$A:$A, 0, IF($B$5="Reading", 3+3, IF($B$5="Writing", 11+3, 14+3))), Helper_AllData!$C:$C, $B$3, Helper_AllData!$D:$D, $B$4), 0)) -> 1.5533333 | C10: =IF(B10="-", "-", IF(B10=0, "-", IF(B10<MAX($B$8:$B$14)*0.8, "🚨 重点突击", "✅ 稳健"))) -> 🚨 重点突击
A11: Part 4 | B11: =IF(OR(AND($B$5="Writing", 4>2), AND($B$5="Listening", 4>5)), "-", IFERROR(AVERAGEIFS(OFFSET(Helper_AllData!$A:$A, 0, IF($B$5="Reading", 3+4, IF($B$5="Writing", 11+4, 14+4))), Helper_AllData!$C:$C, $B$3, Helper_AllData!$D:$D, $B$4), 0)) -> 4.1977778 | C11: =IF(B11="-", "-", IF(B11=0, "-", IF(B11<MAX($B$8:$B$14)*0.8, "🚨 重点突击", "✅ 稳健"))) -> ✅ 稳健
A12: Part 5 | B12: =IF(OR(AND($B$5="Writing", 5>2), AND($B$5="Listening", 5>5)), "-", IFERROR(AVERAGEIFS(OFFSET(Helper_AllData!$A:$A, 0, IF($B$5="Reading", 3+5, IF($B$5="Writing", 11+5, 14+5))), Helper_AllData!$C:$C, $B$3, Helper_AllData!$D:$D, $B$4), 0)) -> 4.7155556 | C12: =IF(B12="-", "-", IF(B12=0, "-", IF(B12<MAX($B$8:$B$14)*0.8, "🚨 重点突击", "✅ 稳健"))) -> ✅ 稳健
A13: Part 6 | B13: =IF(OR(AND($B$5="Writing", 6>2), AND($B$5="Listening", 6>5)), "-", IFERROR(AVERAGEIFS(OFFSET(Helper_AllData!$A:$A, 0, IF($B$5="Reading", 3+6, IF($B$5="Writing", 11+6, 14+6))), Helper_AllData!$C:$C, $B$3, Helper_AllData!$D:$D, $B$4), 0)) -> - | C13: =IF(B13="-", "-", IF(B13=0, "-", IF(B13<MAX($B$8:$B$14)*0.8, "🚨 重点突击", "✅ 稳健"))) -> -
A14: Part 7 | B14: =IF(OR(AND($B$5="Writing", 7>2), AND($B$5="Listening", 7>5)), "-", IFERROR(AVERAGEIFS(OFFSET(Helper_AllData!$A:$A, 0, IF($B$5="Reading", 3+7, IF($B$5="Writing", 11+7, 14+7))), Helper_AllData!$C:$C, $B$3, Helper_AllData!$D:$D, $B$4), 0)) -> - | C14: =IF(B14="-", "-", IF(B14=0, "-", IF(B14<MAX($B$8:$B$14)*0.8, "🚨 重点突击", "✅ 稳健"))) -> -

Sheet 换算标准
A1: Movers R&W分 | B1: 盾 | C1: Movers Listening | D1: 盾.1 | E1: CES分数段 | F1: Unnamed: 5 | G1: Flyers R&W分 | H1: 盾.2 | I1: Flyers Listening分 | J1: 盾.3 | K1: CES分数段.1 | L1: Unnamed: 11 | M1: KET Reading 卷面 | N1: KET Reading 换算 | O1: KET Writing 卷面 | P1: KET Writing 换算 | Q1: KET Listening 卷面 | R1: KET Listening 换算 | S1: PET Reading 卷面 | T1: PET Reading 换算 | U1: PET Writing 卷面 | V1: PET Writing 换算 | W1: PET Listening 卷面 | X1: PET Listening 换算 | Y1: Unnamed: 24 | Z1: Z (等级标准) | AA1: AA (分数线) | AB1: Unnamed: 27 | AC1: FCE Reading Raw | AD1: FCE Reading Scale | AE1: FCE UoE Raw | AF1: FCE UoE Scale | AG1: FCE Writing Raw | AH1: FCE Writing Scale | AI1: FCE Listening Raw | AJ1: FCE Listening Scale | AK1: Unnamed: 36 | AL1: LIVE SET LIST | AM1: LIVE LEVEL LIST | AN1: LIVE NAME LIST
A2: 0 | B2: 1 | C2: 0 | D2: 1 | E2: Below 80 | G2: 0 | H2: 1 | I2: 0 | J2: 1 | K2: 90 - 99 | M2: 13 | N2: 100 | O2: 12 | P2: 102 | Q2: 11 | R2: 100 | S2: 13 | T2: 120 | U2: 16 | V2: 120 | W2: 11 | X2: 120 | Z2: KET Distinction (A) | AA2: 140 | AC2: 0 | AD2: 80 | AE2: 0 | AF2: 80 | AG2: 0 | AH2: 80 | AI2: 0 | AJ2: 80 | AL2: =IFERROR(INDEX(Helper_AllData!$C$2:$C$1000, MATCH(0, INDEX(COUNTIF($AL$1:AL1, Helper_AllData!$C$2:$C$1000)+(Helper_AllData!$C$2:$C$1000=""), 0, 0), 0)), "") -> B1 | AM2: =IFERROR(INDEX(Helper_AllData!$D$2:$D$1000, MATCH(0, INDEX(COUNTIF($AM$1:AM1, Helper_AllData!$D$2:$D$1000)+(Helper_AllData!$D$2:$D$1000=""), 0, 0), 0)), "") -> PET | AN2: =IFERROR(INDEX(Helper_AllData!$A$2:$A$1000, MATCH(0, INDEX(COUNTIF($AN$1:AN1, Helper_AllData!$A$2:$A$1000)+(Helper_AllData!$A$2:$A$1000=""), 0, 0), 0)), "") -> 祝沐妍 Mia Zhu
A3: 18 | B3: 2 | C3: 11 | D3: 2 | E3: 80 - 89 | G3: 18 | H3: 2 | I3: 11 | J3: 2 | K3: 100 - 109 | M3: 14 | N3: 102 | O3: 13 | P3: 105 | Q3: 12 | R3: 103 | S3: 14 | T3: 122 | U3: 17 | V3: 120 | W3: 12 | X3: 122 | Z3: KET Merit (B) | AA3: 133 | AC3: 10 | AD3: 122 | AE3: 7 | AF3: 122 | AG3: 10 | AH3: 122 | AI3: 8 | AJ3: 122 | AL3: =IFERROR(INDEX(Helper_AllData!$C$2:$C$1000, MATCH(0, INDEX(COUNTIF($AL$1:AL2, Helper_AllData!$C$2:$C$1000)+(Helper_AllData!$C$2:$C$1000=""), 0, 0), 0)), "") -> A1 | AM3: =IFERROR(INDEX(Helper_AllData!$D$2:$D$1000, MATCH(0, INDEX(COUNTIF($AM$1:AM2, Helper_AllData!$D$2:$D$1000)+(Helper_AllData!$D$2:$D$1000=""), 0, 0), 0)), "") -> KET | AN3: =IFERROR(INDEX(Helper_AllData!$A$2:$A$1000, MATCH(0, INDEX(COUNTIF($AN$1:AN2, Helper_AllData!$A$2:$A$1000)+(Helper_AllData!$A$2:$A$1000=""), 0, 0), 0)), "") -> 孙雨萱 Annie Sun
A4: 24 | B4: 3 | C4: 14 | D4: 3 | E4: 90 - 99 | G4: 24 | H4: 3 | I4: 14 | J4: 3 | K4: 110 - 119 | M4: 15 | N4: 105 | O4: 14 | P4: 108 | Q4: 13 | R4: 106 | S4: 15 | T4: 124 | U4: 18 | V4: 123 | W4: 13 | X4: 125 | Z4: KET Pass (C) | AA4: 120 | AC4: 16 | AD4: 140 | AE4: 11 | AF4: 140 | AG4: 16 | AH4: 140 | AI4: 12 | AJ4: 140 | AL4: =IFERROR(INDEX(Helper_AllData!$C$2:$C$1000, MATCH(0, INDEX(COUNTIF($AL$1:AL3, Helper_AllData!$C$2:$C$1000)+(Helper_AllData!$C$2:$C$1000=""), 0, 0), 0)), "") -> A2 | AM4: =IFERROR(INDEX(Helper_AllData!$D$2:$D$1000, MATCH(0, INDEX(COUNTIF($AM$1:AM3, Helper_AllData!$D$2:$D$1000)+(Helper_AllData!$D$2:$D$1000=""), 0, 0), 0)), "") -> Flyers | AN4: =IFERROR(INDEX(Helper_AllData!$A$2:$A$1000, MATCH(0, INDEX(COUNTIF($AN$1:AN3, Helper_AllData!$A$2:$A$1000)+(Helper_AllData!$A$2:$A$1000=""), 0, 0), 0)), "") -> 戴依唯 Ivy Dai
A5: 29 | B5: 4 | C5: 18 | D5: 4 | E5: 100 - 109 | G5: 36 | H5: 4 | I5: 18 | J5: 4 | K5: 120 - 132 | M5: 16 | N5: 108 | O5: 15 | P5: 111 | Q5: 14 | R5: 110 | S5: 16 | T5: 126 | U5: 19 | V5: 125 | W5: 14 | X5: 128 | Z5: KET A1 | AA5: 100 | AC5: 24 | AD5: 160 | AE5: 18 | AF5: 160 | AG5: 24 | AH5: 160 | AI5: 18 | AJ5: 160 | AL5: =IFERROR(INDEX(Helper_AllData!$C$2:$C$1000, MATCH(0, INDEX(COUNTIF($AL$1:AL4, Helper_AllData!$C$2:$C$1000)+(Helper_AllData!$C$2:$C$1000=""), 0, 0), 0)), "") -> A4 | AM5: =IFERROR(INDEX(Helper_AllData!$D$2:$D$1000, MATCH(0, INDEX(COUNTIF($AM$1:AM4, Helper_AllData!$D$2:$D$1000)+(Helper_AllData!$D$2:$D$1000=""), 0, 0), 0)), "") -> Movers | AN5: =IFERROR(INDEX(Helper_AllData!$A$2:$A$1000, MATCH(0, INDEX(COUNTIF($AN$1:AN4, Helper_AllData!$A$2:$A$1000)+(Helper_AllData!$A$2:$A$1000=""), 0, 0), 0)), "") -> 项思为 Emma Xiang
A6: 33 | B6: 5 | C6: 21 | D6: 5 | E6: 110 - 119 | G6: 42 | H6: 5 | I6: 21 | J6: 5 | K6: 133 - 139 | M6: 17 | N6: 111 | O6: 16 | P6: 114 | Q6: 15 | R6: 113 | S6: 17 | T6: 128 | U6: 20 | V6: 128 | W6: 15 | X6: 131 | Z6: PET Distinction (A) | AA6: 160 | AC6: 37 | AD6: 180 | AE6: 24 | AF6: 180 | AG6: 34 | AH6: 180 | AI6: 27 | AJ6: 180 | AL6: =IFERROR(INDEX(Helper_AllData!$C$2:$C$1000, MATCH(0, INDEX(COUNTIF($AL$1:AL5, Helper_AllData!$C$2:$C$1000)+(Helper_AllData!$C$2:$C$1000=""), 0, 0), 0)), "") | AM6: =IFERROR(INDEX(Helper_AllData!$D$2:$D$1000, MATCH(0, INDEX(COUNTIF($AM$1:AM5, Helper_AllData!$D$2:$D$1000)+(Helper_AllData!$D$2:$D$1000=""), 0, 0), 0)), "") -> Flyers | AN6: =IFERROR(INDEX(Helper_AllData!$A$2:$A$1000, MATCH(0, INDEX(COUNTIF($AN$1:AN5, Helper_AllData!$A$2:$A$1000)+(Helper_AllData!$A$2:$A$1000=""), 0, 0), 0)), "") -> 孙梓木 Jackson Sun
M7: 18 | N7: 114 | O7: 17 | P7: 117 | Q7: 16 | R7: 116 | S7: 18 | T7: 130 | U7: 21 | V7: 130 | W7: 16 | X7: 134 | Z7: PET Merit (B) | AA7: 153 | AC7: 42 | AD7: 190 | AE7: 28 | AF7: 190 | AG7: 40 | AH7: 190 | AI7: 30 | AJ7: 190 | AL7: =IFERROR(INDEX(Helper_AllData!$C$2:$C$1000, MATCH(0, INDEX(COUNTIF($AL$1:AL6, Helper_AllData!$C$2:$C$1000)+(Helper_AllData!$C$2:$C$1000=""), 0, 0), 0)), "") | AM7: =IFERROR(INDEX(Helper_AllData!$D$2:$D$1000, MATCH(0, INDEX(COUNTIF($AM$1:AM6, Helper_AllData!$D$2:$D$1000)+(Helper_AllData!$D$2:$D$1000=""), 0, 0), 0)), "") -> Starters | AN7: =IFERROR(INDEX(Helper_AllData!$A$2:$A$1000, MATCH(0, INDEX(COUNTIF($AN$1:AN6, Helper_AllData!$A$2:$A$1000)+(Helper_AllData!$A$2:$A$1000=""), 0, 0), 0)), "") -> 孙策 Lucas Sun
M8: 19 | N8: 117 | O8: 18 | P8: 120 | Q8: 17 | R8: 120 | S8: 19 | T8: 132 | U8: 22 | V8: 133 | W8: 17 | X8: 137 | Z8: PET Pass (C) | AA8: 140 | AL8: =IFERROR(INDEX(Helper_AllData!$C$2:$C$1000, MATCH(0, INDEX(COUNTIF($AL$1:AL7, Helper_AllData!$C$2:$C$1000)+(Helper_AllData!$C$2:$C$1000=""), 0, 0), 0)), "") | AM8: =IFERROR(INDEX(Helper_AllData!$D$2:$D$1000, MATCH(0, INDEX(COUNTIF($AM$1:AM7, Helper_AllData!$D$2:$D$1000)+(Helper_AllData!$D$2:$D$1000=""), 0, 0), 0)), "") | AN8: =IFERROR(INDEX(Helper_AllData!$A$2:$A$1000, MATCH(0, INDEX(COUNTIF($AN$1:AN7, Helper_AllData!$A$2:$A$1000)+(Helper_AllData!$A$2:$A$1000=""), 0, 0), 0)), "") -> 徐一濯 Ejay Xu
M9: 20 | N9: 120 | O9: 19 | P9: 123 | Q9: 18 | R9: 123 | S9: 20 | T9: 134 | U9: 23 | V9: 135 | W9: 18 | X9: 140 | Z9: PET A2 | AA9: 120 | AL9: =IFERROR(INDEX(Helper_AllData!$C$2:$C$1000, MATCH(0, INDEX(COUNTIF($AL$1:AL8, Helper_AllData!$C$2:$C$1000)+(Helper_AllData!$C$2:$C$1000=""), 0, 0), 0)), "") | AM9: =IFERROR(INDEX(Helper_AllData!$D$2:$D$1000, MATCH(0, INDEX(COUNTIF($AM$1:AM8, Helper_AllData!$D$2:$D$1000)+(Helper_AllData!$D$2:$D$1000=""), 0, 0), 0)), "") | AN9: =IFERROR(INDEX(Helper_AllData!$A$2:$A$1000, MATCH(0, INDEX(COUNTIF($AN$1:AN8, Helper_AllData!$A$2:$A$1000)+(Helper_AllData!$A$2:$A$1000=""), 0, 0), 0)), "") -> 徐昀 Constance Xu
M10: 21 | N10: 122 | O10: 20 | P10: 125 | Q10: 19 | R10: 126 | S10: 21 | T10: 136 | U10: 24 | V10: 140 | W10: 19 | X10: 144 | AL10: =IFERROR(INDEX(Helper_AllData!$C$2:$C$1000, MATCH(0, INDEX(COUNTIF($AL$1:AL9, Helper_AllData!$C$2:$C$1000)+(Helper_AllData!$C$2:$C$1000=""), 0, 0), 0)), "") | AM10: =IFERROR(INDEX(Helper_AllData!$D$2:$D$1000, MATCH(0, INDEX(COUNTIF($AM$1:AM9, Helper_AllData!$D$2:$D$1000)+(Helper_AllData!$D$2:$D$1000=""), 0, 0), 0)), "") | AN10: =IFERROR(INDEX(Helper_AllData!$A$2:$A$1000, MATCH(0, INDEX(COUNTIF($AN$1:AN9, Helper_AllData!$A$2:$A$1000)+(Helper_AllData!$A$2:$A$1000=""), 0, 0), 0)), "") -> 朱梓琦 Anker Zhu
M11: 22 | N11: 125 | O11: 21 | P11: 128 | Q11: 20 | R11: 130 | S11: 22 | T11: 138 | U11: 25 | V11: 142 | W11: 20 | X11: 148 | AL11: =IFERROR(INDEX(Helper_AllData!$C$2:$C$1000, MATCH(0, INDEX(COUNTIF($AL$1:AL10, Helper_AllData!$C$2:$C$1000)+(Helper_AllData!$C$2:$C$1000=""), 0, 0), 0)), "") | AM11: =IFERROR(INDEX(Helper_AllData!$D$2:$D$1000, MATCH(0, INDEX(COUNTIF($AM$1:AM10, Helper_AllData!$D$2:$D$1000)+(Helper_AllData!$D$2:$D$1000=""), 0, 0), 0)), "") | AN11: =IFERROR(INDEX(Helper_AllData!$A$2:$A$1000, MATCH(0, INDEX(COUNTIF($AN$1:AN10, Helper_AllData!$A$2:$A$1000)+(Helper_AllData!$A$2:$A$1000=""), 0, 0), 0)), "") -> 梁绍启 Sean Liang
M12: 23 | N12: 127 | O12: 22 | P12: 130 | Q12: 21 | R12: 133 | S12: 23 | T12: 140 | U12: 26 | V12: 144 | W12: 21 | X12: 152 | AL12: =IFERROR(INDEX(Helper_AllData!$C$2:$C$1000, MATCH(0, INDEX(COUNTIF($AL$1:AL11, Helper_AllData!$C$2:$C$1000)+(Helper_AllData!$C$2:$C$1000=""), 0, 0), 0)), "") | AM12: =IFERROR(INDEX(Helper_AllData!$D$2:$D$1000, MATCH(0, INDEX(COUNTIF($AM$1:AM11, Helper_AllData!$D$2:$D$1000)+(Helper_AllData!$D$2:$D$1000=""), 0, 0), 0)), "") | AN12: =IFERROR(INDEX(Helper_AllData!$A$2:$A$1000, MATCH(0, INDEX(COUNTIF($AN$1:AN11, Helper_AllData!$A$2:$A$1000)+(Helper_AllData!$A$2:$A$1000=""), 0, 0), 0)), "") -> 詹远 James Zhan
M13: 24 | N13: 130 | O13: 23 | P13: 133 | Q13: 22 | R13: 136 | S13: 24 | T13: 143 | U13: 27 | V13: 146 | W13: 22 | X13: 156 | AL13: =IFERROR(INDEX(Helper_AllData!$C$2:$C$1000, MATCH(0, INDEX(COUNTIF($AL$1:AL12, Helper_AllData!$C$2:$C$1000)+(Helper_AllData!$C$2:$C$1000=""), 0, 0), 0)), "") | AM13: =IFERROR(INDEX(Helper_AllData!$D$2:$D$1000, MATCH(0, INDEX(COUNTIF($AM$1:AM12, Helper_AllData!$D$2:$D$1000)+(Helper_AllData!$D$2:$D$1000=""), 0, 0), 0)), "") | AN13: =IFERROR(INDEX(Helper_AllData!$A$2:$A$1000, MATCH(0, INDEX(COUNTIF($AN$1:AN12, Helper_AllData!$A$2:$A$1000)+(Helper_AllData!$A$2:$A$1000=""), 0, 0), 0)), "") -> 郑楷 Kyle Zheng
M14: 25 | N14: 133 | O14: 24 | P14: 135 | Q14: 23 | R14: 140 | S14: 25 | T14: 146 | U14: 28 | V14: 148 | W14: 23 | X14: 160 | AL14: =IFERROR(INDEX(Helper_AllData!$C$2:$C$1000, MATCH(0, INDEX(COUNTIF($AL$1:AL13, Helper_AllData!$C$2:$C$1000)+(Helper_AllData!$C$2:$C$1000=""), 0, 0), 0)), "") | AM14: =IFERROR(INDEX(Helper_AllData!$D$2:$D$1000, MATCH(0, INDEX(COUNTIF($AM$1:AM13, Helper_AllData!$D$2:$D$1000)+(Helper_AllData!$D$2:$D$1000=""), 0, 0), 0)), "") | AN14: =IFERROR(INDEX(Helper_AllData!$A$2:$A$1000, MATCH(0, INDEX(COUNTIF($AN$1:AN13, Helper_AllData!$A$2:$A$1000)+(Helper_AllData!$A$2:$A$1000=""), 0, 0), 0)), "") -> 陈昱昊 Matte Chen
M15: 26 | N15: 135 | O15: 25 | P15: 138 | Q15: 24 | R15: 145 | S15: 26 | T15: 150 | U15: 29 | V15: 150 | W15: 24 | X15: 165 | AL15: =IFERROR(INDEX(Helper_AllData!$C$2:$C$1000, MATCH(0, INDEX(COUNTIF($AL$1:AL14, Helper_AllData!$C$2:$C$1000)+(Helper_AllData!$C$2:$C$1000=""), 0, 0), 0)), "") | AM15: =IFERROR(INDEX(Helper_AllData!$D$2:$D$1000, MATCH(0, INDEX(COUNTIF($AM$1:AM14, Helper_AllData!$D$2:$D$1000)+(Helper_AllData!$D$2:$D$1000=""), 0, 0), 0)), "") | AN15: =IFERROR(INDEX(Helper_AllData!$A$2:$A$1000, MATCH(0, INDEX(COUNTIF($AN$1:AN14, Helper_AllData!$A$2:$A$1000)+(Helper_AllData!$A$2:$A$1000=""), 0, 0), 0)), "") -> 吴皓轩 Jeffrey Wu
M16: 27 | N16: 137 | O16: 26 | P16: 140 | Q16: 25 | R16: 150 | S16: 27 | T16: 153 | U16: 30 | V16: 152 | W16: 25 | X16: 170 | AL16: =IFERROR(INDEX(Helper_AllData!$C$2:$C$1000, MATCH(0, INDEX(COUNTIF($AL$1:AL15, Helper_AllData!$C$2:$C$1000)+(Helper_AllData!$C$2:$C$1000=""), 0, 0), 0)), "") | AM16: =IFERROR(INDEX(Helper_AllData!$D$2:$D$1000, MATCH(0, INDEX(COUNTIF($AM$1:AM15, Helper_AllData!$D$2:$D$1000)+(Helper_AllData!$D$2:$D$1000=""), 0, 0), 0)), "") | AN16: =IFERROR(INDEX(Helper_AllData!$A$2:$A$1000, MATCH(0, INDEX(COUNTIF($AN$1:AN15, Helper_AllData!$A$2:$A$1000)+(Helper_AllData!$A$2:$A$1000=""), 0, 0), 0)), "") -> 应颜妍 Queen Ying
M17: 28 | N17: 140 | O17: 27 | P17: 143 | S17: 28 | T17: 156 | U17: 31 | V17: 154 | AL17: =IFERROR(INDEX(Helper_AllData!$C$2:$C$1000, MATCH(0, INDEX(COUNTIF($AL$1:AL16, Helper_AllData!$C$2:$C$1000)+(Helper_AllData!$C$2:$C$1000=""), 0, 0), 0)), "") | AM17: =IFERROR(INDEX(Helper_AllData!$D$2:$D$1000, MATCH(0, INDEX(COUNTIF($AM$1:AM16, Helper_AllData!$D$2:$D$1000)+(Helper_AllData!$D$2:$D$1000=""), 0, 0), 0)), "") | AN17: =IFERROR(INDEX(Helper_AllData!$A$2:$A$1000, MATCH(0, INDEX(COUNTIF($AN$1:AN16, Helper_AllData!$A$2:$A$1000)+(Helper_AllData!$A$2:$A$1000=""), 0, 0), 0)), "") -> 王翊名 Mia Wang
M18: 29 | N18: 145 | O18: 28 | P18: 145 | S18: 29 | T18: 160 | U18: 32 | V18: 156 | AL18: =IFERROR(INDEX(Helper_AllData!$C$2:$C$1000, MATCH(0, INDEX(COUNTIF($AL$1:AL17, Helper_AllData!$C$2:$C$1000)+(Helper_AllData!$C$2:$C$1000=""), 0, 0), 0)), "") | AM18: =IFERROR(INDEX(Helper_AllData!$D$2:$D$1000, MATCH(0, INDEX(COUNTIF($AM$1:AM17, Helper_AllData!$D$2:$D$1000)+(Helper_AllData!$D$2:$D$1000=""), 0, 0), 0)), "") | AN18: =IFERROR(INDEX(Helper_AllData!$A$2:$A$1000, MATCH(0, INDEX(COUNTIF($AN$1:AN17, Helper_AllData!$A$2:$A$1000)+(Helper_AllData!$A$2:$A$1000=""), 0, 0), 0)), "") -> 石蕴瑶 Yaoyao Shi
M19: 30 | N19: 150 | O19: 29 | P19: 148 | S19: 30 | T19: 163 | U19: 33 | V19: 158 | AL19: =IFERROR(INDEX(Helper_AllData!$C$2:$C$1000, MATCH(0, INDEX(COUNTIF($AL$1:AL18, Helper_AllData!$C$2:$C$1000)+(Helper_AllData!$C$2:$C$1000=""), 0, 0), 0)), "") | AM19: =IFERROR(INDEX(Helper_AllData!$D$2:$D$1000, MATCH(0, INDEX(COUNTIF($AM$1:AM18, Helper_AllData!$D$2:$D$1000)+(Helper_AllData!$D$2:$D$1000=""), 0, 0), 0)), "") | AN19: =IFERROR(INDEX(Helper_AllData!$A$2:$A$1000, MATCH(0, INDEX(COUNTIF($AN$1:AN18, Helper_AllData!$A$2:$A$1000)+(Helper_AllData!$A$2:$A$1000=""), 0, 0), 0)), "") -> 赵清晔 William Zhao
O20: 30 | P20: 150 | S20: 31 | T20: 166 | U20: 34 | V20: 160 | AL20: =IFERROR(INDEX(Helper_AllData!$C$2:$C$1000, MATCH(0, INDEX(COUNTIF($AL$1:AL19, Helper_AllData!$C$2:$C$1000)+(Helper_AllData!$C$2:$C$1000=""), 0, 0), 0)), "") | AM20: =IFERROR(INDEX(Helper_AllData!$D$2:$D$1000, MATCH(0, INDEX(COUNTIF($AM$1:AM19, Helper_AllData!$D$2:$D$1000)+(Helper_AllData!$D$2:$D$1000=""), 0, 0), 0)), "") | AN20: =IFERROR(INDEX(Helper_AllData!$A$2:$A$1000, MATCH(0, INDEX(COUNTIF($AN$1:AN19, Helper_AllData!$A$2:$A$1000)+(Helper_AllData!$A$2:$A$1000=""), 0, 0), 0)), "") -> 黄翊桐 Yaya Huang
S21: 32 | T21: 170 | U21: 35 | V21: 162 | AL21: =IFERROR(INDEX(Helper_AllData!$C$2:$C$1000, MATCH(0, INDEX(COUNTIF($AL$1:AL20, Helper_AllData!$C$2:$C$1000)+(Helper_AllData!$C$2:$C$1000=""), 0, 0), 0)), "") | AM21: =IFERROR(INDEX(Helper_AllData!$D$2:$D$1000, MATCH(0, INDEX(COUNTIF($AM$1:AM20, Helper_AllData!$D$2:$D$1000)+(Helper_AllData!$D$2:$D$1000=""), 0, 0), 0)), "") | AN21: =IFERROR(INDEX(Helper_AllData!$A$2:$A$1000, MATCH(0, INDEX(COUNTIF($AN$1:AN20, Helper_AllData!$A$2:$A$1000)+(Helper_AllData!$A$2:$A$1000=""), 0, 0), 0)), "") -> 刘泽楷 Nick Liu
U22: 36 | V22: 163 | AL22: =IFERROR(INDEX(Helper_AllData!$C$2:$C$1000, MATCH(0, INDEX(COUNTIF($AL$1:AL21, Helper_AllData!$C$2:$C$1000)+(Helper_AllData!$C$2:$C$1000=""), 0, 0), 0)), "") | AM22: =IFERROR(INDEX(Helper_AllData!$D$2:$D$1000, MATCH(0, INDEX(COUNTIF($AM$1:AM21, Helper_AllData!$D$2:$D$1000)+(Helper_AllData!$D$2:$D$1000=""), 0, 0), 0)), "") | AN22: =IFERROR(INDEX(Helper_AllData!$A$2:$A$1000, MATCH(0, INDEX(COUNTIF($AN$1:AN21, Helper_AllData!$A$2:$A$1000)+(Helper_AllData!$A$2:$A$1000=""), 0, 0), 0)), "") -> 刘野晨 Daniel Liu
U23: 37 | V23: 165 | AL23: =IFERROR(INDEX(Helper_AllData!$C$2:$C$1000, MATCH(0, INDEX(COUNTIF($AL$1:AL22, Helper_AllData!$C$2:$C$1000)+(Helper_AllData!$C$2:$C$1000=""), 0, 0), 0)), "") | AM23: =IFERROR(INDEX(Helper_AllData!$D$2:$D$1000, MATCH(0, INDEX(COUNTIF($AM$1:AM22, Helper_AllData!$D$2:$D$1000)+(Helper_AllData!$D$2:$D$1000=""), 0, 0), 0)), "") | AN23: =IFERROR(INDEX(Helper_AllData!$A$2:$A$1000, MATCH(0, INDEX(COUNTIF($AN$1:AN22, Helper_AllData!$A$2:$A$1000)+(Helper_AllData!$A$2:$A$1000=""), 0, 0), 0)), "") -> 夏添翊 Tommy Xia
U24: 38 | V24: 167 | AL24: =IFERROR(INDEX(Helper_AllData!$C$2:$C$1000, MATCH(0, INDEX(COUNTIF($AL$1:AL23, Helper_AllData!$C$2:$C$1000)+(Helper_AllData!$C$2:$C$1000=""), 0, 0), 0)), "") | AM24: =IFERROR(INDEX(Helper_AllData!$D$2:$D$1000, MATCH(0, INDEX(COUNTIF($AM$1:AM23, Helper_AllData!$D$2:$D$1000)+(Helper_AllData!$D$2:$D$1000=""), 0, 0), 0)), "") | AN24: =IFERROR(INDEX(Helper_AllData!$A$2:$A$1000, MATCH(0, INDEX(COUNTIF($AN$1:AN23, Helper_AllData!$A$2:$A$1000)+(Helper_AllData!$A$2:$A$1000=""), 0, 0), 0)), "") -> 张芮语 Ann Zhang
U25: 39 | V25: 168 | AL25: =IFERROR(INDEX(Helper_AllData!$C$2:$C$1000, MATCH(0, INDEX(COUNTIF($AL$1:AL24, Helper_AllData!$C$2:$C$1000)+(Helper_AllData!$C$2:$C$1000=""), 0, 0), 0)), "") | AM25: =IFERROR(INDEX(Helper_AllData!$D$2:$D$1000, MATCH(0, INDEX(COUNTIF($AM$1:AM24, Helper_AllData!$D$2:$D$1000)+(Helper_AllData!$D$2:$D$1000=""), 0, 0), 0)), "") | AN25: =IFERROR(INDEX(Helper_AllData!$A$2:$A$1000, MATCH(0, INDEX(COUNTIF($AN$1:AN24, Helper_AllData!$A$2:$A$1000)+(Helper_AllData!$A$2:$A$1000=""), 0, 0), 0)), "") -> 张茉凡 Kimberley Zhang
U26: 40 | V26: 170 | AL26: =IFERROR(INDEX(Helper_AllData!$C$2:$C$1000, MATCH(0, INDEX(COUNTIF($AL$1:AL25, Helper_AllData!$C$2:$C$1000)+(Helper_AllData!$C$2:$C$1000=""), 0, 0), 0)), "") | AM26: =IFERROR(INDEX(Helper_AllData!$D$2:$D$1000, MATCH(0, INDEX(COUNTIF($AM$1:AM25, Helper_AllData!$D$2:$D$1000)+(Helper_AllData!$D$2:$D$1000=""), 0, 0), 0)), "") | AN26: =IFERROR(INDEX(Helper_AllData!$A$2:$A$1000, MATCH(0, INDEX(COUNTIF($AN$1:AN25, Helper_AllData!$A$2:$A$1000)+(Helper_AllData!$A$2:$A$1000=""), 0, 0), 0)), "") -> 朱诗淇 Sophia Zhu
AL27: =IFERROR(INDEX(Helper_AllData!$C$2:$C$1000, MATCH(0, INDEX(COUNTIF($AL$1:AL26, Helper_AllData!$C$2:$C$1000)+(Helper_AllData!$C$2:$C$1000=""), 0, 0), 0)), "") | AM27: =IFERROR(INDEX(Helper_AllData!$D$2:$D$1000, MATCH(0, INDEX(COUNTIF($AM$1:AM26, Helper_AllData!$D$2:$D$1000)+(Helper_AllData!$D$2:$D$1000=""), 0, 0), 0)), "") | AN27: =IFERROR(INDEX(Helper_AllData!$A$2:$A$1000, MATCH(0, INDEX(COUNTIF($AN$1:AN26, Helper_AllData!$A$2:$A$1000)+(Helper_AllData!$A$2:$A$1000=""), 0, 0), 0)), "") -> 李翎嫣 Oli Li
AL28: =IFERROR(INDEX(Helper_AllData!$C$2:$C$1000, MATCH(0, INDEX(COUNTIF($AL$1:AL27, Helper_AllData!$C$2:$C$1000)+(Helper_AllData!$C$2:$C$1000=""), 0, 0), 0)), "") | AM28: =IFERROR(INDEX(Helper_AllData!$D$2:$D$1000, MATCH(0, INDEX(COUNTIF($AM$1:AM27, Helper_AllData!$D$2:$D$1000)+(Helper_AllData!$D$2:$D$1000=""), 0, 0), 0)), "") | AN28: =IFERROR(INDEX(Helper_AllData!$A$2:$A$1000, MATCH(0, INDEX(COUNTIF($AN$1:AN27, Helper_AllData!$A$2:$A$1000)+(Helper_AllData!$A$2:$A$1000=""), 0, 0), 0)), "") -> 林奕辰 Eason Lin
AL29: =IFERROR(INDEX(Helper_AllData!$C$2:$C$1000, MATCH(0, INDEX(COUNTIF($AL$1:AL28, Helper_AllData!$C$2:$C$1000)+(Helper_AllData!$C$2:$C$1000=""), 0, 0), 0)), "") | AM29: =IFERROR(INDEX(Helper_AllData!$D$2:$D$1000, MATCH(0, INDEX(COUNTIF($AM$1:AM28, Helper_AllData!$D$2:$D$1000)+(Helper_AllData!$D$2:$D$1000=""), 0, 0), 0)), "") | AN29: =IFERROR(INDEX(Helper_AllData!$A$2:$A$1000, MATCH(0, INDEX(COUNTIF($AN$1:AN28, Helper_AllData!$A$2:$A$1000)+(Helper_AllData!$A$2:$A$1000=""), 0, 0), 0)), "") -> 王薇童 Vera Wang
AL30: =IFERROR(INDEX(Helper_AllData!$C$2:$C$1000, MATCH(0, INDEX(COUNTIF($AL$1:AL29, Helper_AllData!$C$2:$C$1000)+(Helper_AllData!$C$2:$C$1000=""), 0, 0), 0)), "") | AM30: =IFERROR(INDEX(Helper_AllData!$D$2:$D$1000, MATCH(0, INDEX(COUNTIF($AM$1:AM29, Helper_AllData!$D$2:$D$1000)+(Helper_AllData!$D$2:$D$1000=""), 0, 0), 0)), "") | AN30: =IFERROR(INDEX(Helper_AllData!$A$2:$A$1000, MATCH(0, INDEX(COUNTIF($AN$1:AN29, Helper_AllData!$A$2:$A$1000)+(Helper_AllData!$A$2:$A$1000=""), 0, 0), 0)), "") -> 石帛玄 Mambo Shi
AL31: =IFERROR(INDEX(Helper_AllData!$C$2:$C$1000, MATCH(0, INDEX(COUNTIF($AL$1:AL30, Helper_AllData!$C$2:$C$1000)+(Helper_AllData!$C$2:$C$1000=""), 0, 0), 0)), "") | AM31: =IFERROR(INDEX(Helper_AllData!$D$2:$D$1000, MATCH(0, INDEX(COUNTIF($AM$1:AM30, Helper_AllData!$D$2:$D$1000)+(Helper_AllData!$D$2:$D$1000=""), 0, 0), 0)), "") | AN31: =IFERROR(INDEX(Helper_AllData!$A$2:$A$1000, MATCH(0, INDEX(COUNTIF($AN$1:AN30, Helper_AllData!$A$2:$A$1000)+(Helper_AllData!$A$2:$A$1000=""), 0, 0), 0)), "") -> 胡鸿轩 Lucas Hu
AL32: =IFERROR(INDEX(Helper_AllData!$C$2:$C$1000, MATCH(0, INDEX(COUNTIF($AL$1:AL31, Helper_AllData!$C$2:$C$1000)+(Helper_AllData!$C$2:$C$1000=""), 0, 0), 0)), "") | AM32: =IFERROR(INDEX(Helper_AllData!$D$2:$D$1000, MATCH(0, INDEX(COUNTIF($AM$1:AM31, Helper_AllData!$D$2:$D$1000)+(Helper_AllData!$D$2:$D$1000=""), 0, 0), 0)), "") | AN32: =IFERROR(INDEX(Helper_AllData!$A$2:$A$1000, MATCH(0, INDEX(COUNTIF($AN$1:AN31, Helper_AllData!$A$2:$A$1000)+(Helper_AllData!$A$2:$A$1000=""), 0, 0), 0)), "") -> 贺艺婕 Hesper He
AL33: =IFERROR(INDEX(Helper_AllData!$C$2:$C$1000, MATCH(0, INDEX(COUNTIF($AL$1:AL32, Helper_AllData!$C$2:$C$1000)+(Helper_AllData!$C$2:$C$1000=""), 0, 0), 0)), "") | AM33: =IFERROR(INDEX(Helper_AllData!$D$2:$D$1000, MATCH(0, INDEX(COUNTIF($AM$1:AM32, Helper_AllData!$D$2:$D$1000)+(Helper_AllData!$D$2:$D$1000=""), 0, 0), 0)), "") | AN33: =IFERROR(INDEX(Helper_AllData!$A$2:$A$1000, MATCH(0, INDEX(COUNTIF($AN$1:AN32, Helper_AllData!$A$2:$A$1000)+(Helper_AllData!$A$2:$A$1000=""), 0, 0), 0)), "") -> 郭哲宁 Kris Guo
AL34: =IFERROR(INDEX(Helper_AllData!$C$2:$C$1000, MATCH(0, INDEX(COUNTIF($AL$1:AL33, Helper_AllData!$C$2:$C$1000)+(Helper_AllData!$C$2:$C$1000=""), 0, 0), 0)), "") | AM34: =IFERROR(INDEX(Helper_AllData!$D$2:$D$1000, MATCH(0, INDEX(COUNTIF($AM$1:AM33, Helper_AllData!$D$2:$D$1000)+(Helper_AllData!$D$2:$D$1000=""), 0, 0), 0)), "") | AN34: =IFERROR(INDEX(Helper_AllData!$A$2:$A$1000, MATCH(0, INDEX(COUNTIF($AN$1:AN33, Helper_AllData!$A$2:$A$1000)+(Helper_AllData!$A$2:$A$1000=""), 0, 0), 0)), "") -> 陈辰 Chris Chen
AL35: =IFERROR(INDEX(Helper_AllData!$C$2:$C$1000, MATCH(0, INDEX(COUNTIF($AL$1:AL34, Helper_AllData!$C$2:$C$1000)+(Helper_AllData!$C$2:$C$1000=""), 0, 0), 0)), "") | AM35: =IFERROR(INDEX(Helper_AllData!$D$2:$D$1000, MATCH(0, INDEX(COUNTIF($AM$1:AM34, Helper_AllData!$D$2:$D$1000)+(Helper_AllData!$D$2:$D$1000=""), 0, 0), 0)), "") | AN35: =IFERROR(INDEX(Helper_AllData!$A$2:$A$1000, MATCH(0, INDEX(COUNTIF($AN$1:AN34, Helper_AllData!$A$2:$A$1000)+(Helper_AllData!$A$2:$A$1000=""), 0, 0), 0)), "") -> 吕一 Bella Lv
AL36: =IFERROR(INDEX(Helper_AllData!$C$2:$C$1000, MATCH(0, INDEX(COUNTIF($AL$1:AL35, Helper_AllData!$C$2:$C$1000)+(Helper_AllData!$C$2:$C$1000=""), 0, 0), 0)), "") | AM36: =IFERROR(INDEX(Helper_AllData!$D$2:$D$1000, MATCH(0, INDEX(COUNTIF($AM$1:AM35, Helper_AllData!$D$2:$D$1000)+(Helper_AllData!$D$2:$D$1000=""), 0, 0), 0)), "") | AN36: =IFERROR(INDEX(Helper_AllData!$A$2:$A$1000, MATCH(0, INDEX(COUNTIF($AN$1:AN35, Helper_AllData!$A$2:$A$1000)+(Helper_AllData!$A$2:$A$1000=""), 0, 0), 0)), "") -> 李浩辰 Henry Lee
AL37: =IFERROR(INDEX(Helper_AllData!$C$2:$C$1000, MATCH(0, INDEX(COUNTIF($AL$1:AL36, Helper_AllData!$C$2:$C$1000)+(Helper_AllData!$C$2:$C$1000=""), 0, 0), 0)), "") | AM37: =IFERROR(INDEX(Helper_AllData!$D$2:$D$1000, MATCH(0, INDEX(COUNTIF($AM$1:AM36, Helper_AllData!$D$2:$D$1000)+(Helper_AllData!$D$2:$D$1000=""), 0, 0), 0)), "") | AN37: =IFERROR(INDEX(Helper_AllData!$A$2:$A$1000, MATCH(0, INDEX(COUNTIF($AN$1:AN36, Helper_AllData!$A$2:$A$1000)+(Helper_AllData!$A$2:$A$1000=""), 0, 0), 0)), "") -> 胡瀚文 Jayden Hu
AL38: =IFERROR(INDEX(Helper_AllData!$C$2:$C$1000, MATCH(0, INDEX(COUNTIF($AL$1:AL37, Helper_AllData!$C$2:$C$1000)+(Helper_AllData!$C$2:$C$1000=""), 0, 0), 0)), "") | AM38: =IFERROR(INDEX(Helper_AllData!$D$2:$D$1000, MATCH(0, INDEX(COUNTIF($AM$1:AM37, Helper_AllData!$D$2:$D$1000)+(Helper_AllData!$D$2:$D$1000=""), 0, 0), 0)), "") | AN38: =IFERROR(INDEX(Helper_AllData!$A$2:$A$1000, MATCH(0, INDEX(COUNTIF($AN$1:AN37, Helper_AllData!$A$2:$A$1000)+(Helper_AllData!$A$2:$A$1000=""), 0, 0), 0)), "") -> 苏同吴 Lawrence Su
... AL201: =IFERROR(INDEX(Helper_AllData!$C$2:$C$1000, MATCH(0, INDEX(COUNTIF($AL$1:AL200, Helper_AllData!$C$2:$C$1000)+(Helper_AllData!$C$2:$C$1000=""), 0, 0), 0)), "") | AM201: =IFERROR(INDEX(Helper_AllData!$D$2:$D$1000, MATCH(0, INDEX(COUNTIF($AM$1:AM200, Helper_AllData!$D$2:$D$1000)+(Helper_AllData!$D$2:$D$1000=""), 0, 0), 0)), "") | AN201: =IFERROR(INDEX(Helper_AllData!$A$2:$A$1000, MATCH(0, INDEX(COUNTIF($AN$1:AN200, Helper_AllData!$A$2:$A$1000)+(Helper_AllData!$A$2:$A$1000=""), 0, 0), 0)), "")

Sheet 技能库
A1: ID (关键索引) | B1: Level | C1: Type-Part | D1: 满分 | E1: 考察能力 (Skill) | F1: 建议 (Advice)
A2: MOVERS_L-Pt1 | B2: Movers | C2: L-Pt1 | D2: 5 | E2: [听力] 听音辨人 (连线) | F2: 听前先看图，注意人物的衣着颜色和动作特征。
A3: MOVERS_L-Pt2 | B3: Movers | C3: L-Pt2 | D3: 5 | E3: [听力] 听取细节并填空 | F3: 重点练习拼写人名、地名以及抓取数字信息。
A4: MOVERS_L-Pt3 | B4: Movers | C4: L-Pt3 | D4: 5 | E4: [听力] 图片匹配 (星期/活动) | F4: 听完整的句子，注意区分过去几天做了什么，留意干扰项。
A5: MOVERS_L-Pt4 | B5: Movers | C5: L-Pt4 | D5: 5 | E5: [听力] 听取细节 (选择题) | F5: 每个小题都是一个小故事，注意听转折词 (but, no)。
A6: MOVERS_L-Pt5 | B6: Movers | C6: L-Pt5 | D6: 5 | E6: [听力] 听音涂色与书写 | F6: 区分位置介词，准确找到需要涂色的物体，只涂色不画画。
A7: MOVERS_RW-Pt1 | B7: Movers | C7: RW-Pt1 | D7: 5 | E7: [读写] 词汇定义匹配 | F7: 积累名词定义，注意区分功能相似的物品 (如不同种类的动物)。
A8: MOVERS_RW-Pt2 | B8: Movers | C8: RW-Pt2 | D8: 6 | E8: [读写] 补全对话 | F8: 结合上下文语境，注意问句和答句的时态一致性。
A9: MOVERS_RW-Pt3 | B9: Movers | C9: RW-Pt3 | D9: 6 | E9: [读写] 完形填空 (选词) | F9: 通读全文掌握大意，根据词性判断空格处应填名词还是动词。
A10: MOVERS_RW-Pt4 | B10: Movers | C10: RW-Pt4 | D10: 5 | E10: [读写] 多项选择 (语法) | F10: 重点考核语法基础，如名词单复数、代词指代、动词形式。
A11: MOVERS_RW-Pt5 | B11: Movers | C11: RW-Pt5 | D11: 7 | E11: [读写] 阅读故事补全句子 | F11: 练习同义替换，答案通常直接来自文章，不要自己编造。
A12: MOVERS_RW-Pt6 | B12: Movers | C12: RW-Pt6 | D12: 6 | E12: [读写] 看图写句子 | F12: 仔细观察图片，回答问题并写完整的句子，注意拼写。
A13: MOVERS_RW-Pt7 | B13: Movers | C13: RW-Pt7 | D13: 0 | E13: [N/A] Movers无此题型 | F13: 此级别不包含该部分。
... A64: FCE_L-Pt4 | B64: FCE | C64: L-Pt4 | D64: 7 | E64: [听力] 长篇访谈 (多选) | F64: 跟踪采访者的提问逻辑，区分事实陈述与个人观点。

Sheet MSE成绩库
A1: Class | B1: SET | C1: Name | D1: Level | E1: R-Pt1 | F1: R-Pt2 | G1: R-Pt3 | H1: R-Pt4 | I1: R-Pt5 | J1: R-Pt6 | K1: R-Pt7 | L1: R-Raw | M1: R-Scale | N1: W-Pt1 | O1: W-Pt2 | P1: W-Raw | Q1: W-Scale | R1: L-Pt1 | S1: L-Pt2 | T1: L-Pt3 | U1: L-Pt4 | V1: L-Pt5 | W1: L-Raw | X1: L-Scale | Y1: Total-Score | Z1: Grade | AA1: Reading Diagonosis | AB1: Writing Diagonosis | AC1: Listening Diagonosis | AD1: Exam Date
A2: 306 | B2: B1 | C2: 祝沐妍 Mia Zhu | D2: PET | E2: 3 | F2: 1 | G2: 3 | H2: 0 | I2: 3 | J2: 4 | L2: =IF(COUNT(E2:K2)>0, SUM(E2:K2), "") -> 14 | M2: =IF(L2="","", IFERROR(VLOOKUP(L2, IF(D2="KET", 换算标准!$M:$N, IF(D2="PET", 换算标准!$S:$T, 换算标准!$AC:$AD)), 2, TRUE), 0)) -> 122 | P2: =IF(COUNT(N2:O2)>0, SUM(N2:O2), "") | Q2: =IF(P2="","", IFERROR(VLOOKUP(P2, IF(D2="KET", 换算标准!$O:$P, IF(D2="PET", 换算标准!$U:$V, 换算标准!$AG:$AH)), 2, TRUE), 0)) | R2: 7 | S2: 4 | T2: 6 | U2: 4 | W2: =IF(COUNT(R2:V2)>0, SUM(R2:V2), "") -> 21 | X2: =IF(W2="","", IFERROR(VLOOKUP(W2, IF(D2="KET", 换算标准!$Q:$R, IF(D2="PET", 换算标准!$W:$X, 换算标准!$AI:$AJ)), 2, TRUE), 0)) -> 152 | Y2: =IF(COUNT(M2,Q2,X2)>0, AVERAGE(M2,Q2,X2), "") -> 137 | Z2: =IF(Y2="","", IFERROR(VLOOKUP(Y2, 换算标准!$Z:$AA, 1, TRUE), "")) | AA2: =IF(L2="","", "⚠️ 薄弱环节: "&INDEX($E$1:$K$1, MATCH(MIN(E2:K2), E2:K2, 0))&CHAR(10)&"📉 考察能力: "&IFERROR(VLOOKUP(TRIM(D2)&"_"&TRIM(INDEX($E$1:$K$1, MATCH(MIN(E2:K2), E2:K2, 0))), 技能库!$A:$F, 5, 0),"建议查阅考纲")&CHAR(10)&"💡 提升建议: "&IFERROR(VLOOKUP(TRIM(D2)&"_"&TRIM(INDEX($E$1:$K$1, MATCH(MIN(E2:K2), E2:K2, 0))), 技能库!$A:$F, 6, 0),"请针对该题型加强练习")) -> ⚠️ 薄弱环节: R-Pt4 📉 考察能力: [阅读] 句子还原 (填空) 💡 提升建议: 逻辑性极强，需关注代词指代和上下文逻辑连接词。 | AB2: =IF(P2="","", "⚠️ 薄弱环节: "&INDEX($N$1:$O$1, MATCH(MIN(N2:O2), N2:O2, 0))&CHAR(10)&"📉 考察能力: "&IFERROR(VLOOKUP(TRIM(D2)&"_"&TRIM(INDEX($N$1:$O$1, MATCH(MIN(N2:O2), N2:O2, 0))), 技能库!$A:$F, 5, 0),"建议查阅考纲")&CHAR(10)&"💡 提升建议: "&IFERROR(VLOOKUP(TRIM(D2)&"_"&TRIM(INDEX($N$1:$O$1, MATCH(MIN(N2:O2), N2:O2, 0))), 技能库!$A:$F, 6, 0),"请针对该题型加强练习")) | AC2: =IF(W2="","", "⚠️ 薄弱环节: "&INDEX($R$1:$V$1, MATCH(MIN(R2:V2), R2:V2, 0))&CHAR(10)&"📉 考察能力: "&IFERROR(VLOOKUP(TRIM(D2)&"_"&TRIM(INDEX($R$1:$V$1, MATCH(MIN(R2:V2), R2:V2, 0))), 技能库!$A:$F, 5, 0),"建议查阅考纲")&CHAR(10)&"💡 提升建议: "&IFERROR(VLOOKUP(TRIM(D2)&"_"&TRIM(INDEX($R$1:$V$1, MATCH(MIN(R2:V2), R2:V2, 0))), 技能库!$A:$F, 6, 0),"请针对该题型加强练习")) -> ⚠️ 薄弱环节: L-Pt2 📉 考察能力: [听力] 多选 (短对话) 💡 提升建议: 听懂说话人的态度、观点和意图。 | AD2: 2024-01-15
A3: 302 | B3: B1 | C3: 孙雨萱 Annie Sun | D3: PET | E3: 4 | F3: 1 | G3: 4 | H3: 2 | I3: 2 | J3: 4 | L3: =IF(COUNT(E3:K3)>0, SUM(E3:K3), "") -> 17 | M3: =IF(L3="","", IFERROR(VLOOKUP(L3, IF(D3="KET", 换算标准!$M:$N, IF(D3="PET", 换算标准!$S:$T, 换算标准!$AC:$AD)), 2, TRUE), 0)) -> 128 | P3: =IF(COUNT(N3:O3)>0, SUM(N3:O3), "") | Q3: =IF(P3="","", IFERROR(VLOOKUP(P3, IF(D3="KET", 换算标准!$O:$P, IF(D3="PET", 换算标准!$U:$V, 换算标准!$AG:$AH)), 2, TRUE), 0)) | R3: 7 | S3: 5 | T3: 5 | U3: 2 | W3: =IF(COUNT(R3:V3)>0, SUM(R3:V3), "") -> 19 | X3: =IF(W3="","", IFERROR(VLOOKUP(W3, IF(D3="KET", 换算标准!$Q:$R, IF(D3="PET", 换算标准!$W:$X, 换算标准!$AI:$AJ)), 2, TRUE), 0)) -> 144 | Y3: =IF(COUNT(M3,Q3,X3)>0, AVERAGE(M3,Q3,X3), "") -> 136 | Z3: =IF(Y3="","", IFERROR(VLOOKUP(Y3, 换算标准!$Z:$AA, 1, TRUE), "")) | AA3: =IF(L3="","", "⚠️ 薄弱环节: "&INDEX($E$1:$K$1, MATCH(MIN(E3:K3), E3:K3, 0))&CHAR(10)&"📉 考察能力: "&IFERROR(VLOOKUP(TRIM(D3)&"_"&TRIM(INDEX($E$1:$K$1, MATCH(MIN(E3:K3), E3:K3, 0))), 技能库!$A:$F, 5, 0),"建议查阅考纲")&CHAR(10)&"💡 提升建议: "&IFERROR(VLOOKUP(TRIM(D3)&"_"&TRIM(INDEX($E$1:$K$1, MATCH(MIN(E3:K3), E3:K3, 0))), 技能库!$A:$F, 6, 0),"请针对该题型加强练习")) -> ⚠️ 薄弱环节: R-Pt2 📉 考察能力: [阅读] 人物与描述匹配 💡 提升建议: 阅读量大，练习划关键词，寻找完全匹配项。 | AB3: =IF(P3="","", "⚠️ 薄弱环节: "&INDEX($N$1:$O$1, MATCH(MIN(N3:O3), N3:O3, 0))&CHAR(10)&"📉 考察能力: "&IFERROR(VLOOKUP(TRIM(D3)&"_"&TRIM(INDEX($N$1:$O$1, MATCH(MIN(N3:O3), N3:O3, 0))), 技能库!$A:$F, 5, 0),"建议查阅考纲")&CHAR(10)&"💡 提升建议: "&IFERROR(VLOOKUP(TRIM(D3)&"_"&TRIM(INDEX($N$1:$O$1, MATCH(MIN(N3:O3), N3:O3, 0))), 技能库!$A:$F, 6, 0),"请针对该题型加强练习")) | AC3: =IF(W3="","", "⚠️ 薄弱环节: "&INDEX($R$1:$V$1, MATCH(MIN(R3:V3), R3:V3, 0))&CHAR(10)&"📉 考察能力: "&IFERROR(VLOOKUP(TRIM(D3)&"_"&TRIM(INDEX($R$1:$V$1, MATCH(MIN(R3:V3), R3:V3, 0))), 技能库!$A:$F, 5, 0),"建议查阅考纲")&CHAR(10)&"💡 提升建议: "&IFERROR(VLOOKUP(TRIM(D3)&"_"&TRIM(INDEX($R$1:$V$1, MATCH(MIN(R3:V3), R3:V3, 0))), 技能库!$A:$F, 6, 0),"请针对该题型加强练习")) -> ⚠️ 薄弱环节: L-Pt4 📉 考察能力: [听力] 多选 (长采访) 💡 提升建议: 听懂详细的观点阐述，理解对话深层逻辑。 | AD3: 2024-01-15
A4: 302 | B4: B1 | C4: 戴依唯 Ivy Dai | D4: PET | E4: 3 | F4: 5 | G4: 2 | L4: =IF(COUNT(E4:K4)>0, SUM(E4:K4), "") -> 10 | M4: =IF(L4="","", IFERROR(VLOOKUP(L4, IF(D4="KET", 换算标准!$M:$N, IF(D4="PET", 换算标准!$S:$T, 换算标准!$AC:$AD)), 2, TRUE), 0)) -> 0 | P4: =IF(COUNT(N4:O4)>0, SUM(N4:O4), "") | Q4: =IF(P4="","", IFERROR(VLOOKUP(P4, IF(D4="KET", 换算标准!$O:$P, IF(D4="PET", 换算标准!$U:$V, 换算标准!$AG:$AH)), 2, TRUE), 0)) | R4: 7 | S4: 5 | T4: 3 | U4: 3 | W4: =IF(COUNT(R4:V4)>0, SUM(R4:V4), "") -> 18 | X4: =IF(W4="","", IFERROR(VLOOKUP(W4, IF(D4="KET", 换算标准!$Q:$R, IF(D4="PET", 换算标准!$W:$X, 换算标准!$AI:$AJ)), 2, TRUE), 0)) -> 140 | Y4: =IF(COUNT(M4,Q4,X4)>0, AVERAGE(M4,Q4,X4), "") -> 70 | Z4: =IF(Y4="","", IFERROR(VLOOKUP(Y4, 换算标准!$Z:$AA, 1, TRUE), "")) | AA4: =IF(L4="","", "⚠️ 薄弱环节: "&INDEX($E$1:$K$1, MATCH(MIN(E4:K4), E4:K4, 0))&CHAR(10)&"📉 考察能力: "&IFERROR(VLOOKUP(TRIM(D4)&"_"&TRIM(INDEX($E$1:$K$1, MATCH(MIN(E4:K4), E4:K4, 0))), 技能库!$A:$F, 5, 0),"建议查阅考纲")&CHAR(10)&"💡 提升建议: "&IFERROR(VLOOKUP(TRIM(D4)&"_"&TRIM(INDEX($E$1:$K$1, MATCH(MIN(E4:K4), E4:K4, 0))), 技能库!$A:$F, 6, 0),"请针对该题型加强练习")) -> ⚠️ 薄弱环节: R-Pt3 📉 考察能力: [阅读] 长文理解 (多选) 💡 提升建议: 深入理解文章结构，区分事实与观点。 | AB4: =IF(P4="","", "⚠️ 薄弱环节: "&INDEX($N$1:$O$1, MATCH(MIN(N4:O4), N4:O4, 0))&CHAR(10)&"📉 考察能力: "&IFERROR(VLOOKUP(TRIM(D4)&"_"&TRIM(INDEX($N$1:$O$1, MATCH(MIN(N4:O4), N4:O4, 0))), 技能库!$A:$F, 5, 0),"建议查阅考纲")&CHAR(10)&"💡 提升建议: "&IFERROR(VLOOKUP(TRIM(D4)&"_"&TRIM(INDEX($N$1:$O$1, MATCH(MIN(N4:O4), N4:O4, 0))), 技能库!$A:$F, 6, 0),"请针对该题型加强练习")) | AC4: =IF(W4="","", "⚠️ 薄弱环节: "&INDEX($R$1:$V$1, MATCH(MIN(R4:V4), R4:V4, 0))&CHAR(10)&"📉 考察能力: "&IFERROR(VLOOKUP(TRIM(D4)&"_"&TRIM(INDEX($R$1:$V$1, MATCH(MIN(R4:V4), R4:V4, 0))), 技能库!$A:$F, 5, 0),"建议查阅考纲")&CHAR(10)&"💡 提升建议: "&IFERROR(VLOOKUP(TRIM(D4)&"_"&TRIM(INDEX($R$1:$V$1, MATCH(MIN(R4:V4), R4:V4, 0))), 技能库!$A:$F, 6, 0),"请针对该题型加强练习")) -> ⚠️ 薄弱环节: L-Pt3 📉 考察能力: [听力] 填空 (长独白) 💡 提升建议: 听懂说明性文字，捕捉并准确拼写关键名词或数字。 | AD4: 2024-01-15
A5: 302 | B5: B1 | C5: 项思为 Emma Xiang | D5: PET | E5: 1 | F5: 1 | G5: 1 | H5: 1 | I5: 3 | J5: 3 | L5: =IF(COUNT(E5:K5)>0, SUM(E5:K5), "") -> 10 | M5: =IF(L5="","", IFERROR(VLOOKUP(L5, IF(D5="KET", 换算标准!$M:$N, IF(D5="PET", 换算标准!$S:$T, 换算标准!$AC:$AD)), 2, TRUE), 0)) -> 0 | P5: =IF(COUNT(N5:O5)>0, SUM(N5:O5), "") | Q5: =IF(P5="","", IFERROR(VLOOKUP(P5, IF(D5="KET", 换算标准!$O:$P, IF(D5="PET", 换算标准!$U:$V, 换算标准!$AG:$AH)), 2, TRUE), 0)) | R5: 7 | S5: 5 | T5: 3 | U5: 2 | W5: =IF(COUNT(R5:V5)>0, SUM(R5:V5), "") -> 17 | X5: =IF(W5="","", IFERROR(VLOOKUP(W5, IF(D5="KET", 换算标准!$Q:$R, IF(D5="PET", 换算标准!$W:$X, 换算标准!$AI:$AJ)), 2, TRUE), 0)) -> 137 | Y5: =IF(COUNT(M5,Q5,X5)>0, AVERAGE(M5,Q5,X5), "") -> 68.5 | Z5: =IF(Y5="","", IFERROR(VLOOKUP(Y5, 换算标准!$Z:$AA, 1, TRUE), "")) | AA5: =IF(L5="","", "⚠️ 薄弱环节: "&INDEX($E$1:$K$1, MATCH(MIN(E5:K5), E5:K5, 0))&CHAR(10)&"📉 考察能力: "&IFERROR(VLOOKUP(TRIM(D5)&"_"&TRIM(INDEX($E$1:$K$1, MATCH(MIN(E5:K5), E5:K5, 0))), 技能库!$A:$F, 5, 0),"建议查阅考纲")&CHAR(10)&"💡 提升建议: "&IFERROR(VLOOKUP(TRIM(D5)&"_"&TRIM(INDEX($E$1:$K$1, MATCH(MIN(E5:K5), E5:K5, 0))), 技能库!$A:$F, 6, 0),"请针对该题型加强练习")) -> ⚠️ 薄弱环节: R-Pt1 📉 考察能力: [阅读] 短讯息主旨 💡 提升建议: 注意细微的情感态度差异，理解隐含意义。 | AB5: =IF(P5="","", "⚠️ 薄弱环节: "&INDEX($N$1:$O$1, MATCH(MIN(N5:O5), N5:O5, 0))&CHAR(10)&"📉 考察能力: "&IFERROR(VLOOKUP(TRIM(D5)&"_"&TRIM(INDEX($N$1:$O$1, MATCH(MIN(N5:O5), N5:O5, 0))), 技能库!$A:$F, 5, 0),"建议查阅考纲")&CHAR(10)&"💡 提升建议: "&IFERROR(VLOOKUP(TRIM(D5)&"_"&TRIM(INDEX($N$1:$O$1, MATCH(MIN(N5:O5), N5:O5, 0))), 技能库!$A:$F, 6, 0),"请针对该题型加强练习")) | AC5: =IF(W5="","", "⚠️ 薄弱环节: "&INDEX($R$1:$V$1, MATCH(MIN(R5:V5), R5:V5, 0))&CHAR(10)&"📉 考察能力: "&IFERROR(VLOOKUP(TRIM(D5)&"_"&TRIM(INDEX($R$1:$V$1, MATCH(MIN(R5:V5), R5:V5, 0))), 技能库!$A:$F, 5, 0),"建议查阅考纲")&CHAR(10)&"💡 提升建议: "&IFERROR(VLOOKUP(TRIM(D5)&"_"&TRIM(INDEX($R$1:$V$1, MATCH(MIN(R5:V5), R5:V5, 0))), 技能库!$A:$F, 6, 0),"请针对该题型加强练习")) -> ⚠️ 薄弱环节: L-Pt4 📉 考察能力: [听力] 多选 (长采访) 💡 提升建议: 听懂详细的观点阐述，理解对话深层逻辑。 | AD5: 2024-01-15
A6: 302 | B6: B1 | C6: 孙梓木 Jackson Sun | D6: KET | E6: 0 | F6: 6 | G6: 5 | H6: 5 | I6: 4 | L6: =IF(COUNT(E6:K6)>0, SUM(E6:K6), "") -> 20 | M6: =IF(L6="","", IFERROR(VLOOKUP(L6, IF(D6="KET", 换算标准!$M:$N, IF(D6="PET", 换算标准!$S:$T, 换算标准!$AC:$AD)), 2, TRUE), 0)) -> 120 | N6: 7 | O6: 9 | P6: =IF(COUNT(N6:O6)>0, SUM(N6:O6), "") -> 16 | Q6: =IF(P6="","", IFERROR(VLOOKUP(P6, IF(D6="KET", 换算标准!$O:$P, IF(D6="PET", 换算标准!$U:$V, 换算标准!$AG:$AH)), 2, TRUE), 0)) -> 114 | R6: 4 | S6: 3 | T6: 4 | U6: 4 | V6: 5 | W6: =IF(COUNT(R6:V6)>0, SUM(R6:V6), "") -> 20 | X6: =IF(W6="","", IFERROR(VLOOKUP(W6, IF(D6="KET", 换算标准!$Q:$R, IF(D6="PET", 换算标准!$W:$X, 换算标准!$AI:$AJ)), 2, TRUE), 0)) -> 130 | Y6: =IF(COUNT(M6,Q6,X6)>0, AVERAGE(M6,Q6,X6), "") -> 121.33333 | Z6: =IF(Y6="","", IFERROR(VLOOKUP(Y6, 换算标准!$Z:$AA, 1, TRUE), "")) | AA6: =IF(L6="","", "⚠️ 薄弱环节: "&INDEX($E$1:$K$1, MATCH(MIN(E6:K6), E6:K6, 0))&CHAR(10)&"📉 考察能力: "&IFERROR(VLOOKUP(TRIM(D6)&"_"&TRIM(INDEX($E$1:$K$1, MATCH(MIN(E6:K6), E6:K6, 0))), 技能库!$A:$F, 5, 0),"建议查阅考纲")&CHAR(10)&"💡 提升建议: "&IFERROR(VLOOKUP(TRIM(D6)&"_"&TRIM(INDEX($E$1:$K$1, MATCH(MIN(E6:K6), E6:K6, 0))), 技能库!$A:$F, 6, 0),"请针对该题型加强练习")) -> ⚠️ 薄弱环节: R-Pt1 📉 考察能力: [阅读] 短讯息主旨理解 💡 提升建议: 关注生活中的标识、短信，练习找出关键词的同义替换。 | AB6: =IF(P6="","", "⚠️ 薄弱环节: "&INDEX($N$1:$O$1, MATCH(MIN(N6:O6), N6:O6, 0))&CHAR(10)&"📉 考察能力: "&IFERROR(VLOOKUP(TRIM(D6)&"_"&TRIM(INDEX($N$1:$O$1, MATCH(MIN(N6:O6), N6:O6, 0))), 技能库!$A:$F, 5, 0),"建议查阅考纲")&CHAR(10)&"💡 提升建议: "&IFERROR(VLOOKUP(TRIM(D6)&"_"&TRIM(INDEX($N$1:$O$1, MATCH(MIN(N6:O6), N6:O6, 0))), 技能库!$A:$F, 6, 0),"请针对该题型加强练习")) -> ⚠️ 薄弱环节: W-Pt1 📉 考察能力: [写作] 短邮件/便条 💡 提升建议: 必须覆盖所有3个要点，注意语域恰当，无拼写语法错误。 | AC6: =IF(W6="","", "⚠️ 薄弱环节: "&INDEX($R$1:$V$1, MATCH(MIN(R6:V6), R6:V6, 0))&CHAR(10)&"📉 考察能力: "&IFERROR(VLOOKUP(TRIM(D6)&"_"&TRIM(INDEX($R$1:$V$1, MATCH(MIN(R6:V6), R6:V6, 0))), 技能库!$A:$F, 5, 0),"建议查阅考纲")&CHAR(10)&"💡 提升建议: "&IFERROR(VLOOKUP(TRIM(D6)&"_"&TRIM(INDEX($R$1:$V$1, MATCH(MIN(R6:V6), R6:V6, 0))), 技能库!$A:$F, 6, 0),"请针对该题型加强练习")) -> ⚠️ 薄弱环节: L-Pt2 📉 考察能力: [听力] 填空 (信息记录) 💡 提升建议: 强化数字、价格、日期、拼写的听写训练。 | AD6: 2024-01-15
A7: 304 | B7: B1 | C7: 孙策 Lucas Sun | D7: KET | E7: 3 | F7: 7 | G7: 5 | H7: 5 | I7: 3 | L7: =IF(COUNT(E7:K7)>0, SUM(E7:K7), "") -> 23 | M7: =IF(L7="","", IFERROR(VLOOKUP(L7, IF(D7="KET", 换算标准!$M:$N, IF(D7="PET", 换算标准!$S:$T, 换算标准!$AC:$AD)), 2, TRUE), 0)) -> 127 | N7: 0 | O7: 0 | P7: =IF(COUNT(N7:O7)>0, SUM(N7:O7), "") -> 0 | Q7: =IF(P7="","", IFERROR(VLOOKUP(P7, IF(D7="KET", 换算标准!$O:$P, IF(D7="PET", 换算标准!$U:$V, 换算标准!$AG:$AH)), 2, TRUE), 0)) -> 0 | R7: 4 | S7: 1 | T7: 4 | U7: 3 | V7: 3 | W7: =IF(COUNT(R7:V7)>0, SUM(R7:V7), "") -> 15 | X7: =IF(W7="","", IFERROR(VLOOKUP(W7, IF(D7="KET", 换算标准!$Q:$R, IF(D7="PET", 换算标准!$W:$X, 换算标准!$AI:$AJ)), 2, TRUE), 0)) -> 113 | Y7: =IF(COUNT(M7,Q7,X7)>0, AVERAGE(M7,Q7,X7), "") -> 80 | Z7: =IF(Y7="","", IFERROR(VLOOKUP(Y7, 换算标准!$Z:$AA, 1, TRUE), "")) | AA7: =IF(L7="","", "⚠️ 薄弱环节: "&INDEX($E$1:$K$1, MATCH(MIN(E7:K7), E7:K7, 0))&CHAR(10)&"📉 考察能力: "&IFERROR(VLOOKUP(TRIM(D7)&"_"&TRIM(INDEX($E$1:$K$1, MATCH(MIN(E7:K7), E7:K7, 0))), 技能库!$A:$F, 5, 0),"建议查阅考纲")&CHAR(10)&"💡 提升建议: "&IFERROR(VLOOKUP(TRIM(D7)&"_"&TRIM(INDEX($E$1:$K$1, MATCH(MIN(E7:K7), E7:K7, 0))), 技能库!$A:$F, 6, 0),"请针对该题型加强练习")) -> ⚠️ 薄弱环节: R-Pt1 📉 考察能力: [阅读] 短讯息主旨理解 💡 提升建议: 关注生活中的标识、短信，练习找出关键词的同义替换。 | AB7: =IF(P7="","", "⚠️ 薄弱环节: "&INDEX($N$1:$O$1, MATCH(MIN(N7:O7), N7:O7, 0))&CHAR(10)&"📉 考察能力: "&IFERROR(VLOOKUP(TRIM(D7)&"_"&TRIM(INDEX($N$1:$O$1, MATCH(MIN(N7:O7), N7:O7, 0))), 技能库!$A:$F, 5, 0),"建议查阅考纲")&CHAR(10)&"💡 提升建议: "&IFERROR(VLOOKUP(TRIM(D7)&"_"&TRIM(INDEX($N$1:$O$1, MATCH(MIN(N7:O7), N7:O7, 0))), 技能库!$A:$F, 6, 0),"请针对该题型加强练习")) -> ⚠️ 薄弱环节: W-Pt1 📉 考察能力: [写作] 短邮件/便条 💡 提升建议: 必须覆盖所有3个要点，注意语域恰当，无拼写语法错误。 | AC7: =IF(W7="","", "⚠️ 薄弱环节: "&INDEX($R$1:$V$1, MATCH(MIN(R7:V7), R7:V7, 0))&CHAR(10)&"📉 考察能力: "&IFERROR(VLOOKUP(TRIM(D7)&"_"&TRIM(INDEX($R$1:$V$1, MATCH(MIN(R7:V7), R7:V7, 0))), 技能库!$A:$F, 5, 0),"建议查阅考纲")&CHAR(10)&"💡 提升建议: "&IFERROR(VLOOKUP(TRIM(D7)&"_"&TRIM(INDEX($R$1:$V$1, MATCH(MIN(R7:V7), R7:V7, 0))), 技能库!$A:$F, 6, 0),"请针对该题型加强练习")) -> ⚠️ 薄弱环节: L-Pt2 📉 考察能力: [听力] 填空 (信息记录) 💡 提升建议: 强化数字、价格、日期、拼写的听写训练。 | AD7: 2024-01-15
A8: 302 | B8: B1 | C8: 徐一濯 Ejay Xu | D8: KET | E8: 5 | F8: 5 | G8: 5 | H8: 6 | I8: 5 | L8: =IF(COUNT(E8:K8)>0, SUM(E8:K8), "") -> 26 | M8: =IF(L8="","", IFERROR(VLOOKUP(L8, IF(D8="KET", 换算标准!$M:$N, IF(D8="PET", 换算标准!$S:$T, 换算标准!$AC:$AD)), 2, TRUE), 0)) -> 135 | N8: 14 | O8: 13 | P8: =IF(COUNT(N8:O8)>0, SUM(N8:O8), "") -> 27 | Q8: =IF(P8="","", IFERROR(VLOOKUP(P8, IF(D8="KET", 换算标准!$O:$P, IF(D8="PET", 换算标准!$U:$V, 换算标准!$AG:$AH)), 2, TRUE), 0)) -> 143 | R8: 2 | S8: 4 | T8: 5 | U8: 5 | V8: 3 | W8: =IF(COUNT(R8:V8)>0, SUM(R8:V8), "") -> 19 | X8: =IF(W8="","", IFERROR(VLOOKUP(W8, IF(D8="KET", 换算标准!$Q:$R, IF(D8="PET", 换算标准!$W:$X, 换算标准!$AI:$AJ)), 2, TRUE), 0)) -> 126 | Y8: =IF(COUNT(M8,Q8,X8)>0, AVERAGE(M8,Q8,X8), "") -> 134.66667 | Z8: =IF(Y8="","", IFERROR(VLOOKUP(Y8, 换算标准!$Z:$AA, 1, TRUE), "")) | AA8: =IF(L8="","", "⚠️ 薄弱环节: "&INDEX($E$1:$K$1, MATCH(MIN(E8:K8), E8:K8, 0))&CHAR(10)&"📉 考察能力: "&IFERROR(VLOOKUP(TRIM(D8)&"_"&TRIM(INDEX($E$1:$K$1, MATCH(MIN(E8:K8), E8:K8, 0))), 技能库!$A:$F, 5, 0),"建议查阅考纲")&CHAR(10)&"💡 提升建议: "&IFERROR(VLOOKUP(TRIM(D8)&"_"&TRIM(INDEX($E$1:$K$1, MATCH(MIN(E8:K8), E8:K8, 0))), 技能库!$A:$F, 6, 0),"请针对该题型加强练习")) -> ⚠️ 薄弱环节: R-Pt1 📉 考察能力: [阅读] 短讯息主旨理解 💡 提升建议: 关注生活中的标识、短信，练习找出关键词的同义替换。 | AB8: =IF(P8="","", "⚠️ 薄弱环节: "&INDEX($N$1:$O$1, MATCH(MIN(N8:O8), N8:O8, 0))&CHAR(10)&"📉 考察能力: "&IFERROR(VLOOKUP(TRIM(D8)&"_"&TRIM(INDEX($N$1:$O$1, MATCH(MIN(N8:O8), N8:O8, 0))), 技能库!$A:$F, 5, 0),"建议查阅考纲")&CHAR(10)&"💡 提升建议: "&IFERROR(VLOOKUP(TRIM(D8)&"_"&TRIM(INDEX($N$1:$O$1, MATCH(MIN(N8:O8), N8:O8, 0))), 技能库!$A:$F, 6, 0),"请针对该题型加强练习")) -> ⚠️ 薄弱环节: W-Pt2 📉 考察能力: [写作] 看图写故事 💡 提升建议: 运用 linking words (so, because) 串联图片，注意过去时态。 | AC8: =IF(W8="","", "⚠️ 薄弱环节: "&INDEX($R$1:$V$1, MATCH(MIN(R8:V8), R8:V8, 0))&CHAR(10)&"📉 考察能力: "&IFERROR(VLOOKUP(TRIM(D8)&"_"&TRIM(INDEX($R$1:$V$1, MATCH(MIN(R8:V8), R8:V8, 0))), 技能库!$A:$F, 5, 0),"建议查阅考纲")&CHAR(10)&"💡 提升建议: "&IFERROR(VLOOKUP(TRIM(D8)&"_"&TRIM(INDEX($R$1:$V$1, MATCH(MIN(R8:V8), R8:V8, 0))), 技能库!$A:$F, 6, 0),"请针对该题型加强练习")) -> ⚠️ 薄弱环节: L-Pt1 📉 考察能力: [听力] 多选 (关键信息) 💡 提升建议: 警惕干扰项，通常听到的第一个选项是错误的，听完整再选。 | AD8: 2024-01-15
A9: 304 | B9: B1 | C9: 徐昀 Constance Xu | D9: KET | E9: 4 | F9: 7 | G9: 3 | H9: 3 | I9: 3 | L9: =IF(COUNT(E9:K9)>0, SUM(E9:K9), "") -> 20 | M9: =IF(L9="","", IFERROR(VLOOKUP(L9, IF(D9="KET", 换算标准!$M:$N, IF(D9="PET", 换算标准!$S:$T, 换算标准!$AC:$AD)), 2, TRUE), 0)) -> 120 | N9: 0 | O9: 0 | P9: =IF(COUNT(N9:O9)>0, SUM(N9:O9), "") -> 0 | Q9: =IF(P9="","", IFERROR(VLOOKUP(P9, IF(D9="KET", 换算标准!$O:$P, IF(D9="PET", 换算标准!$U:$V, 换算标准!$AG:$AH)), 2, TRUE), 0)) -> 0 | R9: 3 | S9: 1 | T9: 5 | U9: 5 | V9: 5 | W9: =IF(COUNT(R9:V9)>0, SUM(R9:V9), "") -> 19 | X9: =IF(W9="","", IFERROR(VLOOKUP(W9, IF(D9="KET", 换算标准!$Q:$R, IF(D9="PET", 换算标准!$W:$X, 换算标准!$AI:$AJ)), 2, TRUE), 0)) -> 126 | Y9: =IF(COUNT(M9,Q9,X9)>0, AVERAGE(M9,Q9,X9), "") -> 82 | Z9: =IF(Y9="","", IFERROR(VLOOKUP(Y9, 换算标准!$Z:$AA, 1, TRUE), "")) | AA9: =IF(L9="","", "⚠️ 薄弱环节: "&INDEX($E$1:$K$1, MATCH(MIN(E9:K9), E9:K9, 0))&CHAR(10)&"📉 考察能力: "&IFERROR(VLOOKUP(TRIM(D9)&"_"&TRIM(INDEX($E$1:$K$1, MATCH(MIN(E9:K9), E9:K9, 0))), 技能库!$A:$F, 5, 0),"建议查阅考纲")&CHAR(10)&"💡 提升建议: "&IFERROR(VLOOKUP(TRIM(D9)&"_"&TRIM(INDEX($E$1:$K$1, MATCH(MIN(E9:K9), E9:K9, 0))), 技能库!$A:$F, 6, 0),"请针对该题型加强练习")) -> ⚠️ 薄弱环节: R-Pt3 📉 考察能力: [阅读] 长文主旨理解 💡 提升建议: 提升长难句阅读能力，关注段落大意和作者态度。 | AB9: =IF(P9="","", "⚠️ 薄弱环节: "&INDEX($N$1:$O$1, MATCH(MIN(N9:O9), N9:O9, 0))&CHAR(10)&"📉 考察能力: "&IFERROR(VLOOKUP(TRIM(D9)&"_"&TRIM(INDEX($N$1:$O$1, MATCH(MIN(N9:O9), N9:O9, 0))), 技能库!$A:$F, 5, 0),"建议查阅考纲")&CHAR(10)&"💡 提升建议: "&IFERROR(VLOOKUP(TRIM(D9)&"_"&TRIM(INDEX($N$1:$O$1, MATCH(MIN(N9:O9), N9:O9, 0))), 技能库!$A:$F, 6, 0),"请针对该题型加强练习")) -> ⚠️ 薄弱环节: W-Pt1 📉 考察能力: [写作] 短邮件/便条 💡 提升建议: 必须覆盖所有3个要点，注意语域恰当，无拼写语法错误。 | AC9: =IF(W9="","", "⚠️ 薄弱环节: "&INDEX($R$1:$V$1, MATCH(MIN(R9:V9), R9:V9, 0))&CHAR(10)&"📉 考察能力: "&IFERROR(VLOOKUP(TRIM(D9)&"_"&TRIM(INDEX($R$1:$V$1, MATCH(MIN(R9:V9), R9:V9, 0))), 技能库!$A:$F, 5, 0),"建议查阅考纲")&CHAR(10)&"💡 提升建议: "&IFERROR(VLOOKUP(TRIM(D9)&"_"&TRIM(INDEX($R$1:$V$1, MATCH(MIN(R9:V9), R9:V9, 0))), 技能库!$A:$F, 6, 0),"请针对该题型加强练习")) -> ⚠️ 薄弱环节: L-Pt2 📉 考察能力: [听力] 填空 (信息记录) 💡 提升建议: 强化数字、价格、日期、拼写的听写训练。 | AD9: 2024-01-15
A10: 304 | B10: B1 | C10: 朱梓琦 Anker Zhu | D10: KET | E10: 6 | F10: 7 | G10: 4 | H10: 4 | I10: 5 | L10: =IF(COUNT(E10:K10)>0, SUM(E10:K10), "") -> 26 | M10: =IF(L10="","", IFERROR(VLOOKUP(L10, IF(D10="KET", 换算标准!$M:$N, IF(D10="PET", 换算标准!$S:$T, 换算标准!$AC:$AD)), 2, TRUE), 0)) -> 135 | N10: 12 | O10: 10 | P10: =IF(COUNT(N10:O10)>0, SUM(N10:O10), "") -> 22 | Q10: =IF(P10="","", IFERROR(VLOOKUP(P10, IF(D10="KET", 换算标准!$O:$P, IF(D10="PET", 换算标准!$U:$V, 换算标准!$AG:$AH)), 2, TRUE), 0)) -> 130 | R10: 2 | S10: 1 | T10: 3 | U10: 2 | V10: 3 | W10: =IF(COUNT(R10:V10)>0, SUM(R10:V10), "") -> 11 | X10: =IF(W10="","", IFERROR(VLOOKUP(W10, IF(D10="KET", 换算标准!$Q:$R, IF(D10="PET", 换算标准!$W:$X, 换算标准!$AI:$AJ)), 2, TRUE), 0)) -> 100 | Y10: =IF(COUNT(M10,Q10,X10)>0, AVERAGE(M10,Q10,X10), "") -> 121.66667 | Z10: =IF(Y10="","", IFERROR(VLOOKUP(Y10, 换算标准!$Z:$AA, 1, TRUE), "")) | AA10: =IF(L10="","", "⚠️ 薄弱环节: "&INDEX($E$1:$K$1, MATCH(MIN(E10:K10), E10:K10, 0))&CHAR(10)&"📉 考察能力: "&IFERROR(VLOOKUP(TRIM(D10)&"_"&TRIM(INDEX($E$1:$K$1, MATCH(MIN(E10:K10), E10:K10, 0))), 技能库!$A:$F, 5, 0),"建议查阅考纲")&CHAR(10)&"💡 提升建议: "&IFERROR(VLOOKUP(TRIM(D10)&"_"&TRIM(INDEX($E$1:$K$1, MATCH(MIN(E10:K10), E10:K10, 0))), 技能库!$A:$F, 6, 0),"请针对该题型加强练习")) -> ⚠️ 薄弱环节: R-Pt3 📉 考察能力: [阅读] 长文主旨理解 💡 提升建议: 提升长难句阅读能力，关注段落大意和作者态度。 | AB10: =IF(P10="","", "⚠️ 薄弱环节: "&INDEX($N$1:$O$1, MATCH(MIN(N10:O10), N10:O10, 0))&CHAR(10)&"📉 考察能力: "&IFERROR(VLOOKUP(TRIM(D10)&"_"&TRIM(INDEX($N$1:$O$1, MATCH(MIN(N10:O10), N10:O10, 0))), 技能库!$A:$F, 5, 0),"建议查阅考纲")&CHAR(10)&"💡 提升建议: "&IFERROR(VLOOKUP(TRIM(D10)&"_"&TRIM(INDEX($N$1:$O$1, MATCH(MIN(N10:O10), N10:O10, 0))), 技能库!$A:$F, 6, 0),"请针对该题型加强练习")) -> ⚠️ 薄弱环节: W-Pt2 📉 考察能力: [写作] 看图写故事 💡 提升建议: 运用 linking words (so, because) 串联图片，注意过去时态。 | AC10: =IF(W10="","", "⚠️ 薄弱环节: "&INDEX($R$1:$V$1, MATCH(MIN(R10:V10), R10:V10, 0))&CHAR(10)&"📉 考察能力: "&IFERROR(VLOOKUP(TRIM(D10)&"_"&TRIM(INDEX($R$1:$V$1, MATCH(MIN(R10:V10), R10:V10, 0))), 技能库!$A:$F, 5, 0),"建议查阅考纲")&CHAR(10)&"💡 提升建议: "&IFERROR(VLOOKUP(TRIM(D10)&"_"&TRIM(INDEX($R$1:$V$1, MATCH(MIN(R10:V10), R10:V10, 0))), 技能库!$A:$F, 6, 0),"请针对该题型加强练习")) -> ⚠️ 薄弱环节: L-Pt2 📉 考察能力: [听力] 填空 (信息记录) 💡 提升建议: 强化数字、价格、日期、拼写的听写训练。 | AD10: 2024-01-15
A11: 302 | B11: B1 | C11: 梁绍启 Sean Liang | D11: KET | E11: 5 | F11: 5 | G11: 5 | H11: 0 | I11: 0 | L11: =IF(COUNT(E11:K11)>0, SUM(E11:K11), "") -> 15 | M11: =IF(L11="","", IFERROR(VLOOKUP(L11, IF(D11="KET", 换算标准!$M:$N, IF(D11="PET", 换算标准!$S:$T, 换算标准!$AC:$AD)), 2, TRUE), 0)) -> 105 | N11: 13 | O11: 13 | P11: =IF(COUNT(N11:O11)>0, SUM(N11:O11), "") -> 26 | Q11: =IF(P11="","", IFERROR(VLOOKUP(P11, IF(D11="KET", 换算标准!$O:$P, IF(D11="PET", 换算标准!$U:$V, 换算标准!$AG:$AH)), 2, TRUE), 0)) -> 140 | R11: 4 | S11: 2 | T11: 4 | U11: 5 | V11: 5 | W11: =IF(COUNT(R11:V11)>0, SUM(R11:V11), "") -> 20 | X11: =IF(W11="","", IFERROR(VLOOKUP(W11, IF(D11="KET", 换算标准!$Q:$R, IF(D11="PET", 换算标准!$W:$X, 换算标准!$AI:$AJ)), 2, TRUE), 0)) -> 130 | Y11: =IF(COUNT(M11,Q11,X11)>0, AVERAGE(M11,Q11,X11), "") -> 125 | Z11: =IF(Y11="","", IFERROR(VLOOKUP(Y11, 换算标准!$Z:$AA, 1, TRUE), "")) | AA11: =IF(L11="","", "⚠️ 薄弱环节: "&INDEX($E$1:$K$1, MATCH(MIN(E11:K11), E11:K11, 0))&CHAR(10)&"📉 考察能力: "&IFERROR(VLOOKUP(TRIM(D11)&"_"&TRIM(INDEX($E$1:$K$1, MATCH(MIN(E11:K11), E11:K11, 0))), 技能库!$A:$F, 5, 0),"建议查阅考纲")&CHAR(10)&"💡 提升建议: "&IFERROR(VLOOKUP(TRIM(D11)&"_"&TRIM(INDEX($E$1:$K$1, MATCH(MIN(E11:K11), E11:K11, 0))), 技能库!$A:$F, 6, 0),"请针对该题型加强练习")) -> ⚠️ 薄弱环节: R-Pt4 📉 考察能力: [阅读] 完形填空 (词汇) 💡 提升建议: 积累名词、形容词、动词的常见搭配及近义词辨析。 | AB11: =IF(P11="","", "⚠️ 薄弱环节: "&INDEX($N$1:$O$1, MATCH(MIN(N11:O11), N11:O11, 0))&CHAR(10)&"📉 考察能力: "&IFERROR(VLOOKUP(TRIM(D11)&"_"&TRIM(INDEX($N$1:$O$1, MATCH(MIN(N11:O11), N11:O11, 0))), 技能库!$A:$F, 5, 0),"建议查阅考纲")&CHAR(10)&"💡 提升建议: "&IFERROR(VLOOKUP(TRIM(D11)&"_"&TRIM(INDEX($N$1:$O$1, MATCH(MIN(N11:O11), N11:O11, 0))), 技能库!$A:$F, 6, 0),"请针对该题型加强练习")) -> ⚠️ 薄弱环节: W-Pt1 📉 考察能力: [写作] 短邮件/便条 💡 提升建议: 必须覆盖所有3个要点，注意语域恰当，无拼写语法错误。 | AC11: =IF(W11="","", "⚠️ 薄弱环节: "&INDEX($R$1:$V$1, MATCH(MIN(R11:V11), R11:V11, 0))&CHAR(10)&"📉 考察能力: "&IFERROR(VLOOKUP(TRIM(D11)&"_"&TRIM(INDEX($R$1:$V$1, MATCH(MIN(R11:V11), R11:V11, 0))), 技能库!$A:$F, 5, 0),"建议查阅考纲")&CHAR(10)&"💡 提升建议: "&IFERROR(VLOOKUP(TRIM(D11)&"_"&TRIM(INDEX($R$1:$V$1, MATCH(MIN(R11:V11), R11:V11, 0))), 技能库!$A:$F, 6, 0),"请针对该题型加强练习")) -> ⚠️ 薄弱环节: L-Pt2 📉 考察能力: [听力] 填空 (信息记录) 💡 提升建议: 强化数字、价格、日期、拼写的听写训练。 | AD11: 2024-01-15
A12: 304 | B12: B1 | C12: 詹远 James Zhan | D12: KET | E12: 6 | F12: 6 | G12: 5 | H12: 5 | I12: 4 | L12: =IF(COUNT(E12:K12)>0, SUM(E12:K12), "") -> 26 | M12: =IF(L12="","", IFERROR(VLOOKUP(L12, IF(D12="KET", 换算标准!$M:$N, IF(D12="PET", 换算标准!$S:$T, 换算标准!$AC:$AD)), 2, TRUE), 0)) -> 135 | N12: 10 | O12: 10 | P12: =IF(COUNT(N12:O12)>0, SUM(N12:O12), "") -> 20 | Q12: =IF(P12="","", IFERROR(VLOOKUP(P12, IF(D12="KET", 换算标准!$O:$P, IF(D12="PET", 换算标准!$U:$V, 换算标准!$AG:$AH)), 2, TRUE), 0)) -> 125 | R12: 2 | S12: 1 | T12: 5 | U12: 5 | V12: 3 | W12: =IF(COUNT(R12:V12)>0, SUM(R12:V12), "") -> 16 | X12: =IF(W12="","", IFERROR(VLOOKUP(W12, IF(D12="KET", 换算标准!$Q:$R, IF(D12="PET", 换算标准!$W:$X, 换算标准!$AI:$AJ)), 2, TRUE), 0)) -> 116 | Y12: =IF(COUNT(M12,Q12,X12)>0, AVERAGE(M12,Q12,X12), "") -> 125.33333 | Z12: =IF(Y12="","", IFERROR(VLOOKUP(Y12, 换算标准!$Z:$AA, 1, TRUE), "")) | AA12: =IF(L12="","", "⚠️ 薄弱环节: "&INDEX($E$1:$K$1, MATCH(MIN(E12:K12), E12:K12, 0))&CHAR(10)&"📉 考察能力: "&IFERROR(VLOOKUP(TRIM(D12)&"_"&TRIM(INDEX($E$1:$K$1, MATCH(MIN(E12:K12), E12:K12, 0))), 技能库!$A:$F, 5, 0),"建议查阅考纲")&CHAR(10)&"💡 提升建议: "&IFERROR(VLOOKUP(TRIM(D12)&"_"&TRIM(INDEX($E$1:$K$1, MATCH(MIN(E12:K12), E12:K12, 0))), 技能库!$A:$F, 6, 0),"请针对该题型加强练习")) -> ⚠️ 薄弱环节: R-Pt5 📉 考察能力: [阅读] 开放式填空 (语法) 💡 提升建议: 纯语法考核，重点强化介词、代词、连词和时态助动词。 | AB12: =IF(P12="","", "⚠️ 薄弱环节: "&INDEX($N$1:$O$1, MATCH(MIN(N12:O12), N12:O12, 0))&CHAR(10)&"📉 考察能力: "&IFERROR(VLOOKUP(TRIM(D12)&"_"&TRIM(INDEX($N$1:$O$1, MATCH(MIN(N12:O12), N12:O12, 0))), 技能库!$A:$F, 5, 0),"建议查阅考纲")&CHAR(10)&"💡 提升建议: "&IFERROR(VLOOKUP(TRIM(D12)&"_"&TRIM(INDEX($N$1:$O$1, MATCH(MIN(N12:O12), N12:O12, 0))), 技能库!$A:$F, 6, 0),"请针对该题型加强练习")) -> ⚠️ 薄弱环节: W-Pt1 📉 考察能力: [写作] 短邮件/便条 💡 提升建议: 必须覆盖所有3个要点，注意语域恰当，无拼写语法错误。 | AC12: =IF(W12="","", "⚠️ 薄弱环节: "&INDEX($R$1:$V$1, MATCH(MIN(R12:V12), R12:V12, 0))&CHAR(10)&"📉 考察能力: "&IFERROR(VLOOKUP(TRIM(D12)&"_"&TRIM(INDEX($R$1:$V$1, MATCH(MIN(R12:V12), R12:V12, 0))), 技能库!$A:$F, 5, 0),"建议查阅考纲")&CHAR(10)&"💡 提升建议: "&IFERROR(VLOOKUP(TRIM(D12)&"_"&TRIM(INDEX($R$1:$V$1, MATCH(MIN(R12:V12), R12:V12, 0))), 技能库!$A:$F, 6, 0),"请针对该题型加强练习")) -> ⚠️ 薄弱环节: L-Pt2 📉 考察能力: [听力] 填空 (信息记录) 💡 提升建议: 强化数字、价格、日期、拼写的听写训练。 | AD12: 2024-01-15
A13: 302 | B13: B1 | C13: 郑楷 Kyle Zheng | D13: KET | E13: 4 | F13: 5 | G13: 4 | H13: 6 | I13: 3 | L13: =IF(COUNT(E13:K13)>0, SUM(E13:K13), "") -> 22 | M13: =IF(L13="","", IFERROR(VLOOKUP(L13, IF(D13="KET", 换算标准!$M:$N, IF(D13="PET", 换算标准!$S:$T, 换算标准!$AC:$AD)), 2, TRUE), 0)) -> 125 | N13: 10 | O13: 0 | P13: =IF(COUNT(N13:O13)>0, SUM(N13:O13), "") -> 10 | Q13: =IF(P13="","", IFERROR(VLOOKUP(P13, IF(D13="KET", 换算标准!$O:$P, IF(D13="PET", 换算标准!$U:$V, 换算标准!$AG:$AH)), 2, TRUE), 0)) -> 0 | R13: 4 | S13: 3 | T13: 5 | U13: 5 | V13: 2 | W13: =IF(COUNT(R13:V13)>0, SUM(R13:V13), "") -> 19 | X13: =IF(W13="","", IFERROR(VLOOKUP(W13, IF(D13="KET", 换算标准!$Q:$R, IF(D13="PET", 换算标准!$W:$X, 换算标准!$AI:$AJ)), 2, TRUE), 0)) -> 126 | Y13: =IF(COUNT(M13,Q13,X13)>0, AVERAGE(M13,Q13,X13), "") -> 83.666667 | Z13: =IF(Y13="","", IFERROR(VLOOKUP(Y13, 换算标准!$Z:$AA, 1, TRUE), "")) | AA13: =IF(L13="","", "⚠️ 薄弱环节: "&INDEX($E$1:$K$1, MATCH(MIN(E13:K13), E13:K13, 0))&CHAR(10)&"📉 考察能力: "&IFERROR(VLOOKUP(TRIM(D13)&"_"&TRIM(INDEX($E$1:$K$1, MATCH(MIN(E13:K13), E13:K13, 0))), 技能库!$A:$F, 5, 0),"建议查阅考纲")&CHAR(10)&"💡 提升建议: "&IFERROR(VLOOKUP(TRIM(D13)&"_"&TRIM(INDEX($E$1:$K$1, MATCH(MIN(E13:K13), E13:K13, 0))), 技能库!$A:$F, 6, 0),"请针对该题型加强练习")) -> ⚠️ 薄弱环节: R-Pt5 📉 考察能力: [阅读] 开放式填空 (语法) 💡 提升建议: 纯语法考核，重点强化介词、代词、连词和时态助动词。 | AB13: =IF(P13="","", "⚠️ 薄弱环节: "&INDEX($N$1:$O$1, MATCH(MIN(N13:O13), N13:O13, 0))&CHAR(10)&"📉 考察能力: "&IFERROR(VLOOKUP(TRIM(D13)&"_"&TRIM(INDEX($N$1:$O$1, MATCH(MIN(N13:O13), N13:O13, 0))), 技能库!$A:$F, 5, 0),"建议查阅考纲")&CHAR(10)&"💡 提升建议: "&IFERROR(VLOOKUP(TRIM(D13)&"_"&TRIM(INDEX($N$1:$O$1, MATCH(MIN(N13:O13), N13:O13, 0))), 技能库!$A:$F, 6, 0),"请针对该题型加强练习")) -> ⚠️ 薄弱环节: W-Pt2 📉 考察能力: [写作] 看图写故事 💡 提升建议: 运用 linking words (so, because) 串联图片，注意过去时态。 | AC13: =IF(W13="","", "⚠️ 薄弱环节: "&INDEX($R$1:$V$1, MATCH(MIN(R13:V13), R13:V13, 0))&CHAR(10)&"📉 考察能力: "&IFERROR(VLOOKUP(TRIM(D13)&"_"&TRIM(INDEX($R$1:$V$1, MATCH(MIN(R13:V13), R13:V13, 0))), 技能库!$A:$F, 5, 0),"建议查阅考纲")&CHAR(10)&"💡 提升建议: "&IFERROR(VLOOKUP(TRIM(D13)&"_"&TRIM(INDEX($R$1:$V$1, MATCH(MIN(R13:V13), R13:V13, 0))), 技能库!$A:$F, 6, 0),"请针对该题型加强练习")) -> ⚠️ 薄弱环节: L-Pt5 📉 考察能力: [听力] 匹配题 💡 提升建议: 边听边记笔记，排除法是个好工具。 | AD13: 2024-01-15
A14: 304 | B14: B1 | C14: 陈昱昊 Matte Chen | D14: KET | E14: 5 | F14: 5 | G14: 5 | H14: 3 | I14: 2 | L14: =IF(COUNT(E14:K14)>0, SUM(E14:K14), "") -> 20 | M14: =IF(L14="","", IFERROR(VLOOKUP(L14, IF(D14="KET", 换算标准!$M:$N, IF(D14="PET", 换算标准!$S:$T, 换算标准!$AC:$AD)), 2, TRUE), 0)) -> 120 | N14: 8 | O14: 0 | P14: =IF(COUNT(N14:O14)>0, SUM(N14:O14), "") -> 8 | Q14: =IF(P14="","", IFERROR(VLOOKUP(P14, IF(D14="KET", 换算标准!$O:$P, IF(D14="PET", 换算标准!$U:$V, 换算标准!$AG:$AH)), 2, TRUE), 0)) -> 0 | R14: 3 | S14: 4 | T14: 3 | U14: 5 | V14: 3 | W14: =IF(COUNT(R14:V14)>0, SUM(R14:V14), "") -> 18 | X14: =IF(W14="","", IFERROR(VLOOKUP(W14, IF(D14="KET", 换算标准!$Q:$R, IF(D14="PET", 换算标准!$W:$X, 换算标准!$AI:$AJ)), 2, TRUE), 0)) -> 123 | Y14: =IF(COUNT(M14,Q14,X14)>0, AVERAGE(M14,Q14,X14), "") -> 81 | Z14: =IF(Y14="","", IFERROR(VLOOKUP(Y14, 换算标准!$Z:$AA, 1, TRUE), "")) | AA14: =IF(L14="","", "⚠️ 薄弱环节: "&INDEX($E$1:$K$1, MATCH(MIN(E14:K14), E14:K14, 0))&CHAR(10)&"📉 考察能力: "&IFERROR(VLOOKUP(TRIM(D14)&"_"&TRIM(INDEX($E$1:$K$1, MATCH(MIN(E14:K14), E14:K14, 0))), 技能库!$A:$F, 5, 0),"建议查阅考纲")&CHAR(10)&"💡 提升建议: "&IFERROR(VLOOKUP(TRIM(D14)&"_"&TRIM(INDEX($E$1:$K$1, MATCH(MIN(E14:K14), E14:K14, 0))), 技能库!$A:$F, 6, 0),"请针对该题型加强练习")) -> ⚠️ 薄弱环节: R-Pt5 📉 考察能力: [阅读] 开放式填空 (语法) 💡 提升建议: 纯语法考核，重点强化介词、代词、连词和时态助动词。 | AB14: =IF(P14="","", "⚠️ 薄弱环节: "&INDEX($N$1:$O$1, MATCH(MIN(N14:O14), N14:O14, 0))&CHAR(10)&"📉 考察能力: "&IFERROR(VLOOKUP(TRIM(D14)&"_"&TRIM(INDEX($N$1:$O$1, MATCH(MIN(N14:O14), N14:O14, 0))), 技能库!$A:$F, 5, 0),"建议查阅考纲")&CHAR(10)&"💡 提升建议: "&IFERROR(VLOOKUP(TRIM(D14)&"_"&TRIM(INDEX($N$1:$O$1, MATCH(MIN(N14:O14), N14:O14, 0))), 技能库!$A:$F, 6, 0),"请针对该题型加强练习")) -> ⚠️ 薄弱环节: W-Pt2 📉 考察能力: [写作] 看图写故事 💡 提升建议: 运用 linking words (so, because) 串联图片，注意过去时态。 | AC14: =IF(W14="","", "⚠️ 薄弱环节: "&INDEX($R$1:$V$1, MATCH(MIN(R14:V14), R14:V14, 0))&CHAR(10)&"📉 考察能力: "&IFERROR(VLOOKUP(TRIM(D14)&"_"&TRIM(INDEX($R$1:$V$1, MATCH(MIN(R14:V14), R14:V14, 0))), 技能库!$A:$F, 5, 0),"建议查阅考纲")&CHAR(10)&"💡 提升建议: "&IFERROR(VLOOKUP(TRIM(D14)&"_"&TRIM(INDEX($R$1:$V$1, MATCH(MIN(R14:V14), R14:V14, 0))), 技能库!$A:$F, 6, 0),"请针对该题型加强练习")) -> ⚠️ 薄弱环节: L-Pt1 📉 考察能力: [听力] 多选 (关键信息) 💡 提升建议: 警惕干扰项，通常听到的第一个选项是错误的，听完整再选。 | AD14: 2024-01-15
